Workbook
Name lstParameter: Lists!$AM$5:$AM$37
Name lstSector: Lists!$I$5:$I$27
Name lstService: 'Fee Schedule'!$A$6:$A$16
Name setLetterhead_1: Lists!$P$13
Name lstUnit: Lists!$E$5:$E$8
Name T_tblLicenceEffluent: 'Licence Effluent'!$A$5:$L$6
Name T_tSignatory: Lists!$T$5:$V$7
Name T_tOffice: Lists!$AF$5:$AI$7
Name lstClrNo: Lists!$R$5:$R$404
Name lstChemical: Lists!$G$5:$G$56
Name lstLicCategory: Lists!$A$5:$A$10
Name T_tSector: Lists!$I$5:$I$27
Name T_tblIssues: 'Notes & Issues'!$A$5:$G$26
Name lstBillNo: Lists!$X$5:$X$404
Name T_tblCorrespondence: 'Notes & Issues'!$A$31:$I$31
Name lstServiceForBill: Lists!$AK$5:$AK$40
Name lstSchedule: Lists!$AQ$5:$AQ$10
Name T_tblServices: 'Fee Schedule'!$A$6:$D$16
Name setAcctTitle: Lists!$P$11
Name setLetterhead_3: Lists!$P$15
Name T_tblBills: 'Bills & Invoices'!$A$5:$V$32
Name setAcctNo: Lists!$P$10
Name T_tChemical: Lists!$G$5:$G$56
Name setLetterhead_5: Lists!$P$17
Name lstCompanyID: Companies!$A$5:$A$74
Name setSigBillTitle: Lists!$P$8
Name lstRecordGroup: Lists!$M$5:$M$8
Name setSigLicTitle: Lists!$P$6
Name lstBillType: 'Fee Schedule'!$A$20:$A$26
Name T_tRecordGroup: Lists!$M$5:$M$8
Name lstLicType: Lists!$C$5:$C$12
Name lstEffUnit: Lists!$AO$5:$AO$13
Name setSigClrName: Lists!$P$18
Name setSigBillName: Lists!$P$7
Name lstLicID: 'Licences & Certificates'!$A$5:$A$73
Name T_tblClearances: 'Chemical Clearances'!$A$5:$Q$169
Name T_tLicType: Lists!$C$5:$C$12
Name lstPurpose: Lists!$K$5:$K$18
Name setBank: Lists!$P$9
Name T_tEffUnit: Lists!$AO$5:$AO$13
Name setSigClrTitle: Lists!$P$19
Name setLetterhead_2: Lists!$P$14
Name T_tblLicenceVehicles: 'Licence Vehicles'!$A$5:$F$67
Name lstCompanyName: Companies!$B$5:$B$74
Name T_tblCompanies: Companies!$A$5:$J$74
Name T_tblPayments: 'Payments & Receipts'!$A$5:$L$58
Name setSigLicName: Lists!$P$5
Name lstBillPick: Lists!$Y$5:$Y$404
Name lstBillID: 'Bills & Invoices'!$A$5:$A$32
Name T_tParameter: Lists!$AM$5:$AM$37
Name T_tblLicenceChemicals: 'Licence Chemicals'!$A$5:$I$167
Name T_tUnit: Lists!$E$5:$E$8
Name lstSignatory: Lists!$T$5:$T$7
Name T_tPurpose: Lists!$K$5:$K$18
Name T_tblUsers: Users!$A$4:$H$5
Name T_tblLicences: 'Licences & Certificates'!$A$5:$Q$73
Name T_tSchedule: Lists!$AQ$5:$AQ$10
Name T_tLicCategory: Lists!$A$5:$A$10
Name T_tblBillTypes: 'Fee Schedule'!$A$20:$G$26
Name setLetterhead_4: Lists!$P$16

Sheet Main Menu
A1: EPA LIBERIA – ERRS | CHEMICAL MANAGEMENT UNIT (CMU) DATABASE 2026
A2: Main Menu – click a button to open a form or register. Buttons run the Apps Script (menu: CMU Database). First time: CMU Database ▸ Setup ▸ Rebuild Everything. | F2: {=IFERROR(IF(CMU_CodeVersion()="2026.09.26-R","✔ Macros up to date","⚠ Old macros – paste the new code from Macro Setup"),"⚠ Macros not installed – follow the steps on Macro Setup")} -> ⚠ Old macros – paste the new code from Macro Setup
F3: No-login mode: full access enabled
B37: 📘 Open the User Manual
B38: QUICK FIGURES
B39: Companies | C39: =ROWS(Companies!$A$5:$A$74) -> 70 | D39: Licences | E39: =ROWS('Licences & Certificates'!$A$5:$A$73) -> 69 | F39: Clearances | G39: =ROWS('Chemical Clearances'!$A$5:$A$169) -> 165 | H39: Billed / Paid | I39: =TEXT(SUM('Bills & Invoices'!$J$5:$J$32),"$#,##0")&" / "&TEXT(SUM('Payments & Receipts'!$F$5:$F$58),"$#,##0") -> $279,151 / $434,983

Sheet CMU System Doctor
A1: Check | B1: Status | C1: Details
A2: Code version | B2: 2026.09.30-UI | C2: Current Apps Script upgrade version
A3: No-login mode | B3: ON / AVAILABLE | C3: Security is controlled by Google Sheet sharing if no-login is active.
A4: Sheets | B4: CHECK | C4: Missing: Login
A5: Named table ranges | B5: OK | C5: All table ranges found
A6: Formula errors | B6: CHECK | C6: 3 formula error(s) found

Sheet Setup Check
A1: Area | B1: Sheet | C1: Result | D1: Details
A2: Formulas | B2: Login | C2: OK
A3: Formulas | B3: Main Menu | C3: OK
A4: Formulas | B4: User Manual | C4: OK
A5: Formulas | B5: Dashboard | C5: OK
A6: Formulas | B6: Company Form | C6: OK
A7: Formulas | B7: Licence Form | C7: OK
A8: Formulas | B8: Clearance Form | C8: OK
A9: Formulas | B9: Bill Form | C9: OK
A10: Formulas | B10: Payment Form | C10: OK
A11: Formulas | B11: Print CRL | C11: OK
A12: Formulas | B12: Print CIL | C12: OK
A13: Formulas | B13: Print EDL | C13: OK
A14: Formulas | B14: Print EDL RP | C14: 3 error(s) | D14: C82 #N/A, C97 #N/A, C112 #N/A
A15: Formulas | B15: Print Clearance | C15: OK
A16: Formulas | B16: Print Bill | C16: OK
A17: Formulas | B17: Companies | C17: OK
A18: Formulas | B18: Licences & Certificates | C18: OK
A19: Formulas | B19: Licence Chemicals | C19: OK
A20: Formulas | B20: Licence Vehicles | C20: OK
A21: Formulas | B21: Licence Effluent | C21: OK
A22: Formulas | B22: Chemical Clearances | C22: OK
A23: Formulas | B23: Bills & Invoices | C23: OK
A24: Formulas | B24: Payments & Receipts | C24: OK
A25: Formulas | B25: Notes & Issues | C25: OK
A26: Formulas | B26: Fee Schedule | C26: OK
... A59: Buttons | B59: SRC CMU Receipts | C59: OK (1)
A60: Drop-down | B60: Company Form | C60: OK (23 items) | D60: C7 ← Lists!I5:I27
A61: Drop-down | B61: Licence Form | C61: OK (70 items) | D61: C6 ← Companies!B5:B74
A62: Drop-down | B62: Licence Form | C62: OK (6 items) | D62: C7 ← Lists!A5:A10
A63: Drop-down | B63: Licence Form | C63: OK (8 items) | D63: C8 ← Lists!C5:C12
A64: Drop-down | B64: Licence Form | C64: OK (52 items) | D64: C20:C34 ← Lists!G5:G56
A65: Drop-down | B65: Licence Form | C65: OK (4 items) | D65: G20:G34 ← Lists!E5:E8
A66: Drop-down | B66: Licence Form | C66: OK (33 items) | D66: C45:C64 ← Lists!AM5:AM37
A67: Drop-down | B67: Licence Form | C67: OK (9 items) | D67: D45:D64 ← Lists!AO5:AO13
A68: Drop-down | B68: Licence Form | C68: OK (6 items) | D68: G45:G64 ← Lists!AQ5:AQ10
A69: Drop-down | B69: Clearance Form | C69: OK (52 items) | D69: D13:D32 ← Lists!G5:G56
A70: Drop-down | B70: Clearance Form | C70: OK (4 items) | D70: F13:F32 ← Lists!E5:E8
A71: Drop-down | B71: Clearance Form | C71: OK (70 items) | D71: C6 ← Companies!B5:B74
... A97: Drop-down | B97: Payments & Receipts | C97: OK (70 items) | D97: B5:B58 ← Companies!A5:A74

Sheet User Manual
B2: CMU DATABASE – USER MANUAL
B3: EPA Liberia · ERRS · Chemical Management Unit (CMU) Database 2026 · Version 1.0 – 27 September 2026
B4: ← Back to Main Menu
B6: Contents
B8: 1. About this manual
B9: 2. Getting started – opening and signing in
B10: 3. How the workbook is organised
B11: 4. The Main Menu
B12: 5. Record numbers and cell colours
B13: 6. Everyday tasks – step by step
B14: 7. The registers (database)
B15: 8. Dashboard
... B24: This manual explains how to use the CMU DATABASE workbook: signing in, the Main Menu, the five data-entry forms, the registers, printing licences, clearance letters and bills, and routine administration. The screenshots were taken from the live workbook on 27 September 2026, so the records shown in them will differ from what you see as new data is added.
B25: User | C25: Main tasks | F25: Sheets used most
B26: Data-entry officer | C26: Register companies, record licences, clearances, bills and payments; print letters | F26: Forms, Print Centre, Find / Print a Record
B27: Supervisor / Unit head | C27: Monitor activity and outstanding bills; review data issues; approve letters | F27: Dashboard, Registers, Notes & Issues
B28: Administrator | C28: Manage users and passwords, fees, dropdown lists and the macro code | F28: Users & Passwords, Fee Schedule, Lists, Macro Setup
B31: 2. Getting started – opening and signing in
B33: STEP 1 | C33: Open CMU DATABASE.xlsm in the desktop version of Microsoft Excel (Windows). Excel on the web and on phones cannot run the buttons.
B35: STEP 2 | C35: If a yellow SECURITY WARNING bar appears under the ribbon, click Enable Content. Without this, none of the buttons work.
B37: STEP 3 | C37: The Sign In window opens. Type your username and password and press Enter. The first time you sign in you are asked to create your own password (at least 6 characters). After 5 wrong attempts the window closes.
B39: STEP 4 | C39: The Main Menu opens. Check the top-right corner shows ✓ Macros up to date and Signed in: <your name>.
B41: STEP 5 | C41: When you finish, click Log Out on the Main Menu, then save the file with Ctrl + S. Always keep the file as .xlsm (macro-enabled).
B43: ⚠ IMPORTANT: If the corner says 'Old macros' or the buttons do nothing, see Section 12 – Troubleshooting.
B46: 3. How the workbook is organised
B48: Every sheet belongs to one of five groups. The groups use the same colours as the Main Menu buttons, so you can always tell what kind of sheet you are on.
B49: Colour | C49: Group | D49: Sheets | F49: What you do there
C50: Data-entry forms | D50: Company Form, Licence Form, Clearance Form, Bill Form, Payment Form | F50: Add, find, update or delete records
C51: Registers (database) | D51: Companies, Licences & Certificates, Licence Chemicals, Licence Vehicles, Licence Effluent, Chemical Clearances, Bills & Invoices, Payments & Receipts, Notes & Issues | F51: Where every saved record is stored – view, filter and sort
C52: Print Centre | D52: Print CRL, Print CIL, Print EDL, Print EDL RP, Print Clearance, Print Bill | F52: Produce official licences and letters (print, PDF or Word)
C53: Reports & settings | D53: Dashboard, Fee Schedule, Lists, Macro Setup, User Manual | F53: Summaries, fees, dropdown values, macro code, this manual
C54: Source data | D54: SRC BMMC Log, SRC CMU Receipts | F54: Original logs kept for reference – do not edit
B56: A typical case moves through the workbook from left to right, as shown in Figure 1. Every record carries the Company ID, which keeps all the registers linked together.
B66: Figure 1 – The life of a case: from company registration to the printed letter
B68: 4. The Main Menu
B70: The Main Menu is the home screen. Every button opens a form, a register, a print page or a pop-up window. The numbered markers on Figure 2 match the table below it.
B106: Figure 2 – The Main Menu with its nine areas numbered
B108: No. | C108: Area | D108: What it does
B109: 1 | C109: Status | D109: Shows whether the installed macros are current and who is signed in
B110: 2 | C110: Quick Actions | D110: Create New Bill (step-by-step pop-up) and Find / Print a Record (searches every register)
...

Sheet Dashboard
A1: ERRS – CHEMICAL MANAGEMENT UNIT (CMU) | 2026 DATABASE DASHBOARD
A2: All figures are live formulas from the registers (Companies, Licences & Certificates, Chemical Clearances, Payments & Receipts, Bills & Invoices, Data Issues).
A4: Companies | B4: Licences / Certs Numbered | C4: Licences Pending | D4: Clearances (No.) | E4: Total Cleared (MT) | F4: Total Billed (USD) | G4: Total Paid (USD) | H4: Open Data Issues
A5: =ROWS(Companies!$A$5:$A$74) -> 70 | B5: =COUNTIFS('Licences & Certificates'!$K$5:$K$73,"<>") -> 60 | C5: =COUNTIFS('Licences & Certificates'!$N$5:$N$73,"Pending*") -> 9 | D5: =ROWS('Chemical Clearances'!$A$5:$A$169) -> 165 | E5: =SUM('Chemical Clearances'!$J$5:$J$169) -> 15779.981 | F5: =SUM('Bills & Invoices'!$J$5:$J$32) -> 279151 | G5: =SUM('Payments & Receipts'!$F$5:$F$58) -> 434983 | H5: =COUNTIFS('Notes & Issues'!$G$5:$G$26,"Open") -> 8
A7: MONTHLY ACTIVITY 2026 | J7: LICENCES & CERTIFICATES BY CATEGORY
A8: Month | B8: Clearances (No.) | C8: Cleared (MT) | D8: Payments (No.) | E8: Amount Paid (USD) | F8: Amount Billed (USD) | G8: Licences Issued | J8: Licence Category | K8: Total | L8: Active | M8: Issued – expiry not recorded | N8: Pending – no licence no. | P8: OUTSTANDING BILLS (Unpaid / Part paid)
A9: 46023 | B9: =COUNTIFS('Chemical Clearances'!$M$5:$M$169,">="&$A9,'Chemical Clearances'!$M$5:$M$169,"<="&EOMONTH($A9,0)) -> 7 | C9: =SUMIFS('Chemical Clearances'!$J$5:$J$169,'Chemical Clearances'!$M$5:$M$169,">="&$A9,'Chemical Clearances'!$M$5:$M$169,"<="&EOMONTH($A9,0)) -> 655.223 | D9: =COUNTIFS('Payments & Receipts'!$G$5:$G$58,">="&$A9,'Payments & Receipts'!$G$5:$G$58,"<="&EOMONTH($A9,0)) -> 14 | E9: =SUMIFS('Payments & Receipts'!$F$5:$F$58,'Payments & Receipts'!$G$5:$G$58,">="&$A9,'Payments & Receipts'!$G$5:$G$58,"<="&EOMONTH($A9,0)) -> 254776 | F9: =SUMIFS('Bills & Invoices'!$J$5:$J$32,'Bills & Invoices'!$K$5:$K$32,">="&$A9,'Bills & Invoices'!$K$5:$K$32,"<="&EOMONTH($A9,0)) -> 267376 | G9: =COUNTIFS('Licences & Certificates'!$L$5:$L$73,">="&$A9,'Licences & Certificates'!$L$5:$L$73,"<="&EOMONTH($A9,0)) -> 33 | J9: Chemical Registration (CRL) | K9: =COUNTIFS('Licences & Certificates'!$E$5:$E$73,$J9) -> 25 | L9: =COUNTIFS('Licences & Certificates'!$E$5:$E$73,$J9,'Licences & Certificates'!$N$5:$N$73,L$8) -> 5 | M9: =COUNTIFS('Licences & Certificates'!$E$5:$E$73,$J9,'Licences & Certificates'!$N$5:$N$73,M$8) -> 14 | N9: =COUNTIFS('Licences & Certificates'!$E$5:$E$73,$J9,'Licences & Certificates'!$N$5:$N$73,N$8) -> 6 | P9: Bill No. | Q9: Company | R9: Bill Date | S9: Billed (USD) | T9: Paid on bill | U9: Status
A10: =EDATE(A9,1) -> 46054 | B10: =COUNTIFS('Chemical Clearances'!$M$5:$M$169,">="&$A10,'Chemical Clearances'!$M$5:$M$169,"<="&EOMONTH($A10,0)) -> 54 | C10: =SUMIFS('Chemical Clearances'!$J$5:$J$169,'Chemical Clearances'!$M$5:$M$169,">="&$A10,'Chemical Clearances'!$M$5:$M$169,"<="&EOMONTH($A10,0)) -> 3232.8228 | D10: =COUNTIFS('Payments & Receipts'!$G$5:$G$58,">="&$A10,'Payments & Receipts'!$G$5:$G$58,"<="&EOMONTH($A10,0)) -> 8 | E10: =SUMIFS('Payments & Receipts'!$F$5:$F$58,'Payments & Receipts'!$G$5:$G$58,">="&$A10,'Payments & Receipts'!$G$5:$G$58,"<="&EOMONTH($A10,0)) -> 88790 | F10: =SUMIFS('Bills & Invoices'!$J$5:$J$32,'Bills & Invoices'!$K$5:$K$32,">="&$A10,'Bills & Invoices'!$K$5:$K$32,"<="&EOMONTH($A10,0)) -> 6450 | G10: =COUNTIFS('Licences & Certificates'!$L$5:$L$73,">="&$A10,'Licences & Certificates'!$L$5:$L$73,"<="&EOMONTH($A10,0)) -> 0 | J10: Chemical Importation (CIL) | K10: =COUNTIFS('Licences & Certificates'!$E$5:$E$73,$J10) -> 23 | L10: =COUNTIFS('Licences & Certificates'!$E$5:$E$73,$J10,'Licences & Certificates'!$N$5:$N$73,L$8) -> 17 | M10: =COUNTIFS('Licences & Certificates'!$E$5:$E$73,$J10,'Licences & Certificates'!$N$5:$N$73,M$8) -> 5 | N10: =COUNTIFS('Licences & Certificates'!$E$5:$E$73,$J10,'Licences & Certificates'!$N$5:$N$73,N$8) -> 1 | P10: =IFERROR(__xludf.DUMMYFUNCTION("IFERROR(FILTER(CHOOSECOLS(Lists!X5:AD404,1,3,4,5,6,7),(Lists!AD5:AD404=""Unpaid"")+(Lists!AD5:AD404=""Part paid"")),""No outstanding bills"")"),"BN-2026-019") -> BN-2026-019 | Q10: =IFERROR(__xludf.DUMMYFUNCTION("""COMPUTED_VALUE"""),"REAT Liberia") -> REAT Liberia | R10: =IFERROR(__xludf.DUMMYFUNCTION("""COMPUTED_VALUE"""),46064.0) -> 46064 | S10: =IFERROR(__xludf.DUMMYFUNCTION("""COMPUTED_VALUE"""),1500.0) -> 1500 | T10: =IFERROR(__xludf.DUMMYFUNCTION("""COMPUTED_VALUE"""),0.0) -> 0 | U10: =IFERROR(__xludf.DUMMYFUNCTION("""COMPUTED_VALUE"""),"Unpaid") -> Unpaid
A11: =EDATE(A10,1) -> 46082 | B11: =COUNTIFS('Chemical Clearances'!$M$5:$M$169,">="&$A11,'Chemical Clearances'!$M$5:$M$169,"<="&EOMONTH($A11,0)) -> 13 | C11: =SUMIFS('Chemical Clearances'!$J$5:$J$169,'Chemical Clearances'!$M$5:$M$169,">="&$A11,'Chemical Clearances'!$M$5:$M$169,"<="&EOMONTH($A11,0)) -> 2135.476 | D11: =COUNTIFS('Payments & Receipts'!$G$5:$G$58,">="&$A11,'Payments & Receipts'!$G$5:$G$58,"<="&EOMONTH($A11,0)) -> 8 | E11: =SUMIFS('Payments & Receipts'!$F$5:$F$58,'Payments & Receipts'!$G$5:$G$58,">="&$A11,'Payments & Receipts'!$G$5:$G$58,"<="&EOMONTH($A11,0)) -> 22311 | F11: =SUMIFS('Bills & Invoices'!$J$5:$J$32,'Bills & Invoices'!$K$5:$K$32,">="&$A11,'Bills & Invoices'!$K$5:$K$32,"<="&EOMONTH($A11,0)) -> 0 | G11: =COUNTIFS('Licences & Certificates'!$L$5:$L$73,">="&$A11,'Licences & Certificates'!$L$5:$L$73,"<="&EOMONTH($A11,0)) -> 0 | J11: Effluent Discharge (EDL) | K11: =COUNTIFS('Licences & Certificates'!$E$5:$E$73,$J11) -> 12 | L11: =COUNTIFS('Licences & Certificates'!$E$5:$E$73,$J11,'Licences & Certificates'!$N$5:$N$73,L$8) -> 1 | M11: =COUNTIFS('Licences & Certificates'!$E$5:$E$73,$J11,'Licences & Certificates'!$N$5:$N$73,M$8) -> 9 | N11: =COUNTIFS('Licences & Certificates'!$E$5:$E$73,$J11,'Licences & Certificates'!$N$5:$N$73,N$8) -> 2 | P11: =IFERROR(__xludf.DUMMYFUNCTION("""COMPUTED_VALUE"""),"BN-2026-017") -> BN-2026-017 | Q11: =IFERROR(__xludf.DUMMYFUNCTION("""COMPUTED_VALUE"""),"Kwado Energy") -> Kwado Energy | R11: =IFERROR(__xludf.DUMMYFUNCTION("""COMPUTED_VALUE"""),46065.0) -> 46065 | S11: =IFERROR(__xludf.DUMMYFUNCTION("""COMPUTED_VALUE"""),1500.0) -> 1500 | T11: =IFERROR(__xludf.DUMMYFUNCTION("""COMPUTED_VALUE"""),0.0) -> 0 | U11: =IFERROR(__xludf.DUMMYFUNCTION("""COMPUTED_VALUE"""),"Unpaid") -> Unpaid
A12: =EDATE(A11,1) -> 46113 | B12: =COUNTIFS('Chemical Clearances'!$M$5:$M$169,">="&$A12,'Chemical Clearances'!$M$5:$M$169,"<="&EOMONTH($A12,0)) -> 24 | C12: =SUMIFS('Chemical Clearances'!$J$5:$J$169,'Chemical Clearances'!$M$5:$M$169,">="&$A12,'Chemical Clearances'!$M$5:$M$169,"<="&EOMONTH($A12,0)) -> 1286.378 | D12: =COUNTIFS('Payments & Receipts'!$G$5:$G$58,">="&$A12,'Payments & Receipts'!$G$5:$G$58,"<="&EOMONTH($A12,0)) -> 4 | E12: =SUMIFS('Payments & Receipts'!$F$5:$F$58,'Payments & Receipts'!$G$5:$G$58,">="&$A12,'Payments & Receipts'!$G$5:$G$58,"<="&EOMONTH($A12,0)) -> 4925 | F12: =SUMIFS('Bills & Invoices'!$J$5:$J$32,'Bills & Invoices'!$K$5:$K$32,">="&$A12,'Bills & Invoices'!$K$5:$K$32,"<="&EOMONTH($A12,0)) -> 0 | G12: =COUNTIFS('Licences & Certificates'!$L$5:$L$73,">="&$A12,'Licences & Certificates'!$L$5:$L$73,"<="&EOMONTH($A12,0)) -> 0 | J12: Dewatering & Sedimentation Pond | K12: =COUNTIFS('Licences & Certificates'!$E$5:$E$73,$J12) -> 2 | L12: =COUNTIFS('Licences & Certificates'!$E$5:$E$73,$J12,'Licences & Certificates'!$N$5:$N$73,L$8) -> 2 | M12: =COUNTIFS('Licences & Certificates'!$E$5:$E$73,$J12,'Licences & Certificates'!$N$5:$N$73,M$8) -> 0 | N12: =COUNTIFS('Licences & Certificates'!$E$5:$E$73,$J12,'Licences & Certificates'!$N$5:$N$73,N$8) -> 0 | P12: =IFERROR(__xludf.DUMMYFUNCTION("""COMPUTED_VALUE"""),"BN-2026-011") -> BN-2026-011 | Q12: =IFERROR(__xludf.DUMMYFUNCTION("""COMPUTED_VALUE"""),"Liberia Soap and Detergent Company") -> Liberia Soap and Detergent Company | R12: =IFERROR(__xludf.DUMMYFUNCTION("""COMPUTED_VALUE"""),46048.0) -> 46048 | S12: =IFERROR(__xludf.DUMMYFUNCTION("""COMPUTED_VALUE"""),7550.0) -> 7550 | T12: =IFERROR(__xludf.DUMMYFUNCTION("""COMPUTED_VALUE"""),0.0) -> 0 | U12: =IFERROR(__xludf.DUMMYFUNCTION("""COMPUTED_VALUE"""),"Unpaid") -> Unpaid
A13: =EDATE(A12,1) -> 46143 | B13: =COUNTIFS('Chemical Clearances'!$M$5:$M$169,">="&$A13,'Chemical Clearances'!$M$5:$M$169,"<="&EOMONTH($A13,0)) -> 18 | C13: =SUMIFS('Chemical Clearances'!$J$5:$J$169,'Chemical Clearances'!$M$5:$M$169,">="&$A13,'Chemical Clearances'!$M$5:$M$169,"<="&EOMONTH($A13,0)) -> 653.9035 | D13: =COUNTIFS('Payments & Receipts'!$G$5:$G$58,">="&$A13,'Payments & Receipts'!$G$5:$G$58,"<="&EOMONTH($A13,0)) -> 6 | E13: =SUMIFS('Payments & Receipts'!$F$5:$F$58,'Payments & Receipts'!$G$5:$G$58,">="&$A13,'Payments & Receipts'!$G$5:$G$58,"<="&EOMONTH($A13,0)) -> 13325 | F13: =SUMIFS('Bills & Invoices'!$J$5:$J$32,'Bills & Invoices'!$K$5:$K$32,">="&$A13,'Bills & Invoices'!$K$5:$K$32,"<="&EOMONTH($A13,0)) -> 0 | G13: =COUNTIFS('Licences & Certificates'!$L$5:$L$73,">="&$A13,'Licences & Certificates'!$L$5:$L$73,"<="&EOMONTH($A13,0)) -> 0 | J13: Fumigation | K13: =COUNTIFS('Licences & Certificates'!$E$5:$E$73,$J13) -> 1 | L13: =COUNTIFS('Licences & Certificates'!$E$5:$E$73,$J13,'Licences & Certificates'!$N$5:$N$73,L$8) -> 1 | M13: =COUNTIFS('Licences & Certificates'!$E$5:$E$73,$J13,'Licences & Certificates'!$N$5:$N$73,M$8) -> 0 | N13: =COUNTIFS('Licences & Certificates'!$E$5:$E$73,$J13,'Licences & Certificates'!$N$5:$N$73,N$8) -> 0 | P13: =IFERROR(__xludf.DUMMYFUNCTION("""COMPUTED_VALUE"""),"BN-2026-010") -> BN-2026-010 | Q13: =IFERROR(__xludf.DUMMYFUNCTION("""COMPUTED_VALUE"""),"Fouani Brothers") -> Fouani Brothers | R13: =IFERROR(__xludf.DUMMYFUNCTION("""COMPUTED_VALUE"""),46048.0) -> 46048 | S13: =IFERROR(__xludf.DUMMYFUNCTION("""COMPUTED_VALUE"""),3000.0) -> 3000 | T13: =IFERROR(__xludf.DUMMYFUNCTION("""COMPUTED_VALUE"""),0.0) -> 0 | U13: =IFERROR(__xludf.DUMMYFUNCTION("""COMPUTED_VALUE"""),"Unpaid") -> Unpaid
A14: =EDATE(A13,1) -> 46174 | B14: =COUNTIFS('Chemical Clearances'!$M$5:$M$169,">="&$A14,'Chemical Clearances'!$M$5:$M$169,"<="&EOMONTH($A14,0)) -> 7 | C14: =SUMIFS('Chemical Clearances'!$J$5:$J$169,'Chemical Clearances'!$M$5:$M$169,">="&$A14,'Chemical Clearances'!$M$5:$M$169,"<="&EOMONTH($A14,0)) -> 457.264 | D14: =COUNTIFS('Payments & Receipts'!$G$5:$G$58,">="&$A14,'Payments & Receipts'!$G$5:$G$58,"<="&EOMONTH($A14,0)) -> 3 | E14: =SUMIFS('Payments & Receipts'!$F$5:$F$58,'Payments & Receipts'!$G$5:$G$58,">="&$A14,'Payments & Receipts'!$G$5:$G$58,"<="&EOMONTH($A14,0)) -> 10275 | F14: =SUMIFS('Bills & Invoices'!$J$5:$J$32,'Bills & Invoices'!$K$5:$K$32,">="&$A14,'Bills & Invoices'!$K$5:$K$32,"<="&EOMONTH($A14,0)) -> 0 | G14: =COUNTIFS('Licences & Certificates'!$L$5:$L$73,">="&$A14,'Licences & Certificates'!$L$5:$L$73,"<="&EOMONTH($A14,0)) -> 0 | J14: Chemical Transportation | K14: =COUNTIFS('Licences & Certificates'!$E$5:$E$73,$J14) -> 6 | L14: =COUNTIFS('Licences & Certificates'!$E$5:$E$73,$J14,'Licences & Certificates'!$N$5:$N$73,L$8) -> 6 | M14: =COUNTIFS('Licences & Certificates'!$E$5:$E$73,$J14,'Licences & Certificates'!$N$5:$N$73,M$8) -> 0 | N14: =COUNTIFS('Licences & Certificates'!$E$5:$E$73,$J14,'Licences & Certificates'!$N$5:$N$73,N$8) -> 0 | P14: =IFERROR(__xludf.DUMMYFUNCTION("""COMPUTED_VALUE"""),"BN-2026-006") -> BN-2026-006 | Q14: =IFERROR(__xludf.DUMMYFUNCTION("""COMPUTED_VALUE"""),"T Waste Recycling & Fumigation Inc.") -> T Waste Recycling & Fumigation Inc. | R14: =IFERROR(__xludf.DUMMYFUNCTION("""COMPUTED_VALUE"""),46036.0) -> 46036 | S14: =IFERROR(__xludf.DUMMYFUNCTION("""COMPUTED_VALUE"""),275.0) -> 275 | T14: =IFERROR(__xludf.DUMMYFUNCTION("""COMPUTED_VALUE"""),0.0) -> 0 | U14: =IFERROR(__xludf.DUMMYFUNCTION("""COMPUTED_VALUE"""),"Unpaid") -> Unpaid
A15: =EDATE(A14,1) -> 46204 | B15: =COUNTIFS('Chemical Clearances'!$M$5:$M$169,">="&$A15,'Chemical Clearances'!$M$5:$M$169,"<="&EOMONTH($A15,0)) -> 10 | C15: =SUMIFS('Chemical Clearances'!$J$5:$J$169,'Chemical Clearances'!$M$5:$M$169,">="&$A15,'Chemical Clearances'!$M$5:$M$169,"<="&EOMONTH($A15,0)) -> 1015.841 | D15: =COUNTIFS('Payments & Receipts'!$G$5:$G$58,">="&$A15,'Payments & Receipts'!$G$5:$G$58,"<="&EOMONTH($A15,0)) -> 4 | E15: =SUMIFS('Payments & Receipts'!$F$5:$F$58,'Payments & Receipts'!$G$5:$G$58,">="&$A15,'Payments & Receipts'!$G$5:$G$58,"<="&EOMONTH($A15,0)) -> 8435 | F15: =SUMIFS('Bills & Invoices'!$J$5:$J$32,'Bills & Invoices'!$K$5:$K$32,">="&$A15,'Bills & Invoices'!$K$5:$K$32,"<="&EOMONTH($A15,0)) -> 0 | G15: =COUNTIFS('Licences & Certificates'!$L$5:$L$73,">="&$A15,'Licences & Certificates'!$L$5:$L$73,"<="&EOMONTH($A15,0)) -> 0 | J15: TOTAL | K15: =SUM(K9:K14) -> 69 | L15: =SUM(L9:L14) -> 32 | M15: =SUM(M9:M14) -> 28 | N15: =SUM(N9:N14) -> 9 | P15: =IFERROR(__xludf.DUMMYFUNCTION("""COMPUTED_VALUE"""),"BN-2026-005") -> BN-2026-005 | Q15: =IFERROR(__xludf.DUMMYFUNCTION("""COMPUTED_VALUE"""),"Efficient Professional Services Inc.") -> Efficient Professional Services Inc. | R15: =IFERROR(__xludf.DUMMYFUNCTION("""COMPUTED_VALUE"""),46043.0) -> 46043 | S15: =IFERROR(__xludf.DUMMYFUNCTION("""COMPUTED_VALUE"""),275.0) -> 275 | T15: =IFERROR(__xludf.DUMMYFUNCTION("""COMPUTED_VALUE"""),0.0) -> 0 | U15: =IFERROR(__xludf.DUMMYFUNCTION("""COMPUTED_VALUE"""),"Unpaid") -> Unpaid
A16: =EDATE(A15,1) -> 46235 | B16: =COUNTIFS('Chemical Clearances'!$M$5:$M$169,">="&$A16,'Chemical Clearances'!$M$5:$M$169,"<="&EOMONTH($A16,0)) -> 3 | C16: =SUMIFS('Chemical Clearances'!$J$5:$J$169,'Chemical Clearances'!$M$5:$M$169,">="&$A16,'Chemical Clearances'!$M$5:$M$169,"<="&EOMONTH($A16,0)) -> 764.158 | D16: =COUNTIFS('Payments & Receipts'!$G$5:$G$58,">="&$A16,'Payments & Receipts'!$G$5:$G$58,"<="&EOMONTH($A16,0)) -> 2 | E16: =SUMIFS('Payments & Receipts'!$F$5:$F$58,'Payments & Receipts'!$G$5:$G$58,">="&$A16,'Payments & Receipts'!$G$5:$G$58,"<="&EOMONTH($A16,0)) -> 12455 | F16: =SUMIFS('Bills & Invoices'!$J$5:$J$32,'Bills & Invoices'!$K$5:$K$32,">="&$A16,'Bills & Invoices'!$K$5:$K$32,"<="&EOMONTH($A16,0)) -> 0 | G16: =COUNTIFS('Licences & Certificates'!$L$5:$L$73,">="&$A16,'Licences & Certificates'!$L$5:$L$73,"<="&EOMONTH($A16,0)) -> 0 | P16: =IFERROR(__xludf.DUMMYFUNCTION("""COMPUTED_VALUE"""),"BN-2026-003") -> BN-2026-003 | Q16: =IFERROR(__xludf.DUMMYFUNCTION("""COMPUTED_VALUE"""),"Mano Manufacturing Company (MANCO)") -> Mano Manufacturing Company (MANCO) | R16: =IFERROR(__xludf.DUMMYFUNCTION("""COMPUTED_VALUE"""),46030.0) -> 46030 | S16: =IFERROR(__xludf.DUMMYFUNCTION("""COMPUTED_VALUE"""),1500.0) -> 1500 | T16: =IFERROR(__xludf.DUMMYFUNCTION("""COMPUTED_VALUE"""),0.0) -> 0 | U16: =IFERROR(__xludf.DUMMYFUNCTION("""COMPUTED_VALUE"""),"Unpaid") -> Unpaid
A17: =EDATE(A16,1) -> 46266 | B17: =COUNTIFS('Chemical Clearances'!$M$5:$M$169,">="&$A17,'Chemical Clearances'!$M$5:$M$169,"<="&EOMONTH($A17,0)) -> 11 | C17: =SUMIFS('Chemical Clearances'!$J$5:$J$169,'Chemical Clearances'!$M$5:$M$169,">="&$A17,'Chemical Clearances'!$M$5:$M$169,"<="&EOMONTH($A17,0)) -> 2482.2512 | D17: =COUNTIFS('Payments & Receipts'!$G$5:$G$58,">="&$A17,'Payments & Receipts'!$G$5:$G$58,"<="&EOMONTH($A17,0)) -> 3 | E17: =SUMIFS('Payments & Receipts'!$F$5:$F$58,'Payments & Receipts'!$G$5:$G$58,">="&$A17,'Payments & Receipts'!$G$5:$G$58,"<="&EOMONTH($A17,0)) -> 7541 | F17: =SUMIFS('Bills & Invoices'!$J$5:$J$32,'Bills & Invoices'!$K$5:$K$32,">="&$A17,'Bills & Invoices'!$K$5:$K$32,"<="&EOMONTH($A17,0)) -> 0 | G17: =COUNTIFS('Licences & Certificates'!$L$5:$L$73,">="&$A17,'Licences & Certificates'!$L$5:$L$73,"<="&EOMONTH($A17,0)) -> 0 | J17: BILLS – PAYMENT STATUS | P17: =IFERROR(__xludf.DUMMYFUNCTION("""COMPUTED_VALUE"""),"BN-2026-001") -> BN-2026-001 | Q17: =IFERROR(__xludf.DUMMYFUNCTION("""COMPUTED_VALUE"""),"Delta Plastics Inc.") -> Delta Plastics Inc. | R17: =IFERROR(__xludf.DUMMYFUNCTION("""COMPUTED_VALUE"""),46030.0) -> 46030 | S17: =IFERROR(__xludf.DUMMYFUNCTION("""COMPUTED_VALUE"""),1500.0) -> 1500 | T17: =IFERROR(__xludf.DUMMYFUNCTION("""COMPUTED_VALUE"""),0.0) -> 0 | U17: =IFERROR(__xludf.DUMMYFUNCTION("""COMPUTED_VALUE"""),"Unpaid") -> Unpaid
A18: =EDATE(A17,1) -> 46296 | B18: =COUNTIFS('Chemical Clearances'!$M$5:$M$169,">="&$A18,'Chemical Clearances'!$M$5:$M$169,"<="&EOMONTH($A18,0)) -> 0 | C18: =SUMIFS('Chemical Clearances'!$J$5:$J$169,'Chemical Clearances'!$M$5:$M$169,">="&$A18,'Chemical Clearances'!$M$5:$M$169,"<="&EOMONTH($A18,0)) -> 0 | D18: =COUNTIFS('Payments & Receipts'!$G$5:$G$58,">="&$A18,'Payments & Receipts'!$G$5:$G$58,"<="&EOMONTH($A18,0)) -> 0 | E18: =SUMIFS('Payments & Receipts'!$F$5:$F$58,'Payments & Receipts'!$G$5:$G$58,">="&$A18,'Payments & Receipts'!$G$5:$G$58,"<="&EOMONTH($A18,0)) -> 0 | F18: =SUMIFS('Bills & Invoices'!$J$5:$J$32,'Bills & Invoices'!$K$5:$K$32,">="&$A18,'Bills & Invoices'!$K$5:$K$32,"<="&EOMONTH($A18,0)) -> 0 | G18: =COUNTIFS('Licences & Certificates'!$L$5:$L$73,">="&$A18,'Licences & Certificates'!$L$5:$L$73,"<="&EOMONTH($A18,0)) -> 0 | J18: Payment Status | K18: Bills (No.) | L18: Amount Billed (USD)
A19: =EDATE(A18,1) -> 46327 | B19: =COUNTIFS('Chemical Clearances'!$M$5:$M$169,">="&$A19,'Chemical Clearances'!$M$5:$M$169,"<="&EOMONTH($A19,0)) -> 0 | C19: =SUMIFS('Chemical Clearances'!$J$5:$J$169,'Chemical Clearances'!$M$5:$M$169,">="&$A19,'Chemical Clearances'!$M$5:$M$169,"<="&EOMONTH($A19,0)) -> 0 | D19: =COUNTIFS('Payments & Receipts'!$G$5:$G$58,">="&$A19,'Payments & Receipts'!$G$5:$G$58,"<="&EOMONTH($A19,0)) -> 0 | E19: =SUMIFS('Payments & Receipts'!$F$5:$F$58,'Payments & Receipts'!$G$5:$G$58,">="&$A19,'Payments & Receipts'!$G$5:$G$58,"<="&EOMONTH($A19,0)) -> 0 | F19: =SUMIFS('Bills & Invoices'!$J$5:$J$32,'Bills & Invoices'!$K$5:$K$32,">="&$A19,'Bills & Invoices'!$K$5:$K$32,"<="&EOMONTH($A19,0)) -> 0 | G19: =COUNTIFS('Licences & Certificates'!$L$5:$L$73,">="&$A19,'Licences & Certificates'!$L$5:$L$73,"<="&EOMONTH($A19,0)) -> 0 | J19: Paid | K19: =COUNTIFS('Bills & Invoices'!$N$5:$N$32,$J19) -> 15 | L19: =SUMIFS('Bills & Invoices'!$J$5:$J$32,'Bills & Invoices'!$N$5:$N$32,$J19) -> 257501
A20: =EDATE(A19,1) -> 46357 | B20: =COUNTIFS('Chemical Clearances'!$M$5:$M$169,">="&$A20,'Chemical Clearances'!$M$5:$M$169,"<="&EOMONTH($A20,0)) -> 0 | C20: =SUMIFS('Chemical Clearances'!$J$5:$J$169,'Chemical Clearances'!$M$5:$M$169,">="&$A20,'Chemical Clearances'!$M$5:$M$169,"<="&EOMONTH($A20,0)) -> 0 | D20: =COUNTIFS('Payments & Receipts'!$G$5:$G$58,">="&$A20,'Payments & Receipts'!$G$5:$G$58,"<="&EOMONTH($A20,0)) -> 0 | E20: =SUMIFS('Payments & Receipts'!$F$5:$F$58,'Payments & Receipts'!$G$5:$G$58,">="&$A20,'Payments & Receipts'!$G$5:$G$58,"<="&EOMONTH($A20,0)) -> 0 | F20: =SUMIFS('Bills & Invoices'!$J$5:$J$32,'Bills & Invoices'!$K$5:$K$32,">="&$A20,'Bills & Invoices'!$K$5:$K$32,"<="&EOMONTH($A20,0)) -> 0 | G20: =COUNTIFS('Licences & Certificates'!$L$5:$L$73,">="&$A20,'Licences & Certificates'!$L$5:$L$73,"<="&EOMONTH($A20,0)) -> 0 | J20: Part paid | K20: =COUNTIFS('Bills & Invoices'!$N$5:$N$32,$J20) -> 2 | L20: =SUMIFS('Bills & Invoices'!$J$5:$J$32,'Bills & Invoices'!$N$5:$N$32,$J20) -> 4550
A21: Date not recorded | B21: =COUNTIFS('Chemical Clearances'!$M$5:$M$169,"") -> 18 | C21: =SUMIFS('Chemical Clearances'!$J$5:$J$169,'Chemical Clearances'!$M$5:$M$169,"") -> 3096.664 | D21: =COUNTIFS('Payments & Receipts'!$G$5:$G$58,"") -> 2 | E21: =SUMIFS('Payments & Receipts'!$F$5:$F$58,'Payments & Receipts'!$G$5:$G$58,"") -> 12150 | F21: =SUMIFS('Bills & Invoices'!$J$5:$J$32,'Bills & Invoices'!$K$5:$K$32,"") -> 5325 | G21: =COUNTIFS('Licences & Certificates'!$L$5:$L$73,"",'Licences & Certificates'!$K$5:$K$73,"<>") -> 27 | J21: No payment on record | K21: =COUNTIFS('Bills & Invoices'!$N$5:$N$32,$J21) -> 11 | L21: =SUMIFS('Bills & Invoices'!$J$5:$J$32,'Bills & Invoices'!$N$5:$N$32,$J21) -> 17100
A22: TOTAL | B22: =SUM(B9:B21) -> 165 | C22: =SUM(C9:C21) -> 15779.981 | D22: =SUM(D9:D21) -> 54 | E22: =SUM(E9:E21) -> 434983 | F22: =SUM(F9:F21) -> 279151 | G22: =SUM(G9:G21) -> 60 | J22: TOTAL | K22: =SUM(K19:K21) -> 28 | L22: =SUM(L19:L21) -> 279151
A23: Check vs registers (should be 0) | B23: =B22-ROWS('Chemical Clearances'!$A$5:$A$169) -> 0 | C23: =ROUND(C22-SUM('Chemical Clearances'!$J$5:$J$169),3) -> 0 | D23: =D22-ROWS('Payments & Receipts'!$A$5:$A$58) -> 0 | E23: =E22-SUM('Payments & Receipts'!$F$5:$F$58) -> 0 | F23: =F22-SUM('Bills & Invoices'!$J$5:$J$32) -> 0
A25: CLEARANCES BY CHEMICAL (standardised names)
A26: Chemical (Standard) | B26: Shipments (No.) | C26: Qty (kg) | D26: Qty (MT) | E26: % of Total kg
A27: Ferric Chloride | B27: =COUNTIFS('Chemical Clearances'!$F$5:$F$169,$A27) -> 10 | C27: =SUMIFS('Chemical Clearances'!$I$5:$I$169,'Chemical Clearances'!$F$5:$F$169,$A27) -> 3308166 | D27: =C27/1000 -> 3308.166 | E27: =IF(SUM('Chemical Clearances'!$I$5:$I$169)=0,0,C27/SUM('Chemical Clearances'!$I$5:$I$169)) -> 0.20964321
A28: Explosives (Emulsion) | B28: =COUNTIFS('Chemical Clearances'!$F$5:$F$169,$A28) -> 6 | C28: =SUMIFS('Chemical Clearances'!$I$5:$I$169,'Chemical Clearances'!$F$5:$F$169,$A28) -> 2338291 | D28: =C28/1000 -> 2338.291 | E28: =IF(SUM('Chemical Clearances'!$I$5:$I$169)=0,0,C28/SUM('Chemical Clearances'!$I$5:$I$169)) -> 0.14818085
A29: Sodium Cyanide | B29: =COUNTIFS('Chemical Clearances'!$F$5:$F$169,$A29) -> 4 | C29: =SUMIFS('Chemical Clearances'!$I$5:$I$169,'Chemical Clearances'!$F$5:$F$169,$A29) -> 1937500 | D29: =C29/1000 -> 1937.5 | E29: =IF(SUM('Chemical Clearances'!$I$5:$I$169)=0,0,C29/SUM('Chemical Clearances'!$I$5:$I$169)) -> 0.12278215
A30: Akshot 160 (Alkali Curing Accelerator) | B30: =COUNTIFS('Chemical Clearances'!$F$5:$F$169,$A30) -> 10 | C30: =SUMIFS('Chemical Clearances'!$I$5:$I$169,'Chemical Clearances'!$F$5:$F$169,$A30) -> 1211138 | D30: =C30/1000 -> 1211.138 | E30: =IF(SUM('Chemical Clearances'!$I$5:$I$169)=0,0,C30/SUM('Chemical Clearances'!$I$5:$I$169)) -> 0.076751548
A31: Sodium Metabisulphite (SMBS) | B31: =COUNTIFS('Chemical Clearances'!$F$5:$F$169,$A31) -> 9 | C31: =SUMIFS('Chemical Clearances'!$I$5:$I$169,'Chemical Clearances'!$F$5:$F$169,$A31) -> 1146800 | D31: =C31/1000 -> 1146.8 | E31: =IF(SUM('Chemical Clearances'!$I$5:$I$169)=0,0,C31/SUM('Chemical Clearances'!$I$5:$I$169)) -> 0.072674357
A32: Polymers (PE / PP) | B32: =COUNTIFS('Chemical Clearances'!$F$5:$F$169,$A32) -> 10 | C32: =SUMIFS('Chemical Clearances'!$I$5:$I$169,'Chemical Clearances'!$F$5:$F$169,$A32) -> 1013149 | D32: =C32/1000 -> 1013.149 | E32: =IF(SUM('Chemical Clearances'!$I$5:$I$169)=0,0,C32/SUM('Chemical Clearances'!$I$5:$I$169)) -> 0.064204702
A33: Methyltrialkyl Ammonium Chloride | B33: =COUNTIFS('Chemical Clearances'!$F$5:$F$169,$A33) -> 1 | C33: =SUMIFS('Chemical Clearances'!$I$5:$I$169,'Chemical Clearances'!$F$5:$F$169,$A33) -> 860000 | D33: =C33/1000 -> 860 | E33: =IF(SUM('Chemical Clearances'!$I$5:$I$169)=0,0,C33/SUM('Chemical Clearances'!$I$5:$I$169)) -> 0.05449943
A34: Paint & Coatings | B34: =COUNTIFS('Chemical Clearances'!$F$5:$F$169,$A34) -> 4 | C34: =SUMIFS('Chemical Clearances'!$I$5:$I$169,'Chemical Clearances'!$F$5:$F$169,$A34) -> 628256.8 | D34: =C34/1000 -> 628.2568 | E34: =IF(SUM('Chemical Clearances'!$I$5:$I$169)=0,0,C34/SUM('Chemical Clearances'!$I$5:$I$169)) -> 0.039813532
A35: Caustic Soda (Sodium Hydroxide) | B35: =COUNTIFS('Chemical Clearances'!$F$5:$F$169,$A35) -> 14 | C35: =SUMIFS('Chemical Clearances'!$I$5:$I$169,'Chemical Clearances'!$F$5:$F$169,$A35) -> 744260 | D35: =C35/1000 -> 744.26 | E35: =IF(SUM('Chemical Clearances'!$I$5:$I$169)=0,0,C35/SUM('Chemical Clearances'!$I$5:$I$169)) -> 0.047164821
A36: Activated Carbon | B36: =COUNTIFS('Chemical Clearances'!$F$5:$F$169,$A36) -> 4 | C36: =SUMIFS('Chemical Clearances'!$I$5:$I$169,'Chemical Clearances'!$F$5:$F$169,$A36) -> 568175.7 | D36: =C36/1000 -> 568.1757 | E36: =IF(SUM('Chemical Clearances'!$I$5:$I$169)=0,0,C36/SUM('Chemical Clearances'!$I$5:$I$169)) -> 0.036006107
A37: Hydrated Lime | B37: =COUNTIFS('Chemical Clearances'!$F$5:$F$169,$A37) -> 2 | C37: =SUMIFS('Chemical Clearances'!$I$5:$I$169,'Chemical Clearances'!$F$5:$F$169,$A37) -> 501960 | D37: =C37/1000 -> 501.96 | E37: =IF(SUM('Chemical Clearances'!$I$5:$I$169)=0,0,C37/SUM('Chemical Clearances'!$I$5:$I$169)) -> 0.031809923
A38: Akhidralin (Shotcrete Fluidifier) | B38: =COUNTIFS('Chemical Clearances'!$F$5:$F$169,$A38) -> 3 | C38: =SUMIFS('Chemical Clearances'!$I$5:$I$169,'Chemical Clearances'!$F$5:$F$169,$A38) -> 191380 | D38: =C38/1000 -> 191.38 | E38: =IF(SUM('Chemical Clearances'!$I$5:$I$169)=0,0,C38/SUM('Chemical Clearances'!$I$5:$I$169)) -> 0.012128024
... A73: Magnesium Perchlorate | B73: =COUNTIFS('Chemical Clearances'!$F$5:$F$169,$A73) -> 1 | C73: =SUMIFS('Chemical Clearances'!$I$5:$I$169,'Chemical Clearances'!$F$5:$F$169,$A73) -> 6 | D73: =C73/1000 -> 0.006 | E73: =IF(SUM('Chemical Clearances'!$I$5:$I$169)=0,0,C73/SUM('Chemical Clearances'!$I$5:$I$169)) -> 3.8022858e-07
A74: TOTAL | B74: =SUM(B27:B73) -> 155 | C74: =SUM(C27:C73) -> 15406054 | D74: =SUM(D27:D73) -> 15406.054 | E74: =SUM(E27:E73) -> 0.97630371

Sheet Company Form
A1: ERRS – CHEMICAL MANAGEMENT UNIT | COMPANY REGISTRATION FORM
A2: Yellow cells are inputs. * = required. To edit: type the ID in row 5 and click Find, change fields, then click Update. Leave the ID blank and click Save New for a new record.
B4: FORM STATUS | C4: =IF(IF(C6="","Company Name; ","")="","✔ Ready to save","✖ Missing: "&IF(C6="","Company Name; ","")) -> ✖ Missing: Company Name;
B5: Company ID | D5: {="Leave blank for a NEW record (next ID: "&"CMU-"&TEXT(SUMPRODUCT(MAX(--MID(Companies!$A$5:$A$74,5,4)))+1,"000")&"). Type an existing ID and click Find to edit."} -> Leave blank for a NEW record (next ID: CMU-071). Type an existing ID and click Find to edit.
B6: Company Name * | D6: =IF(C6="","Enter the official company name",IF(COUNTIF(Companies!$B$5:$B$74,C6)>0,"⚠ Already in register (OK only if updating)","✔ New company")) -> Enter the official company name
B7: Sector / Activity | D7: Choose from list (add new sectors on the Lists sheet)
B8: Location | D8: Street / town, county
B9: Other Names Recorded | C9: =IFERROR(__xludf.DUMMYFUNCTION("AI(""Fill an appropriate value for this cell based on the table context"")"),"") | D9: Other spellings used on documents, separated by ;

Sheet Licence Form
A1: ERRS – CHEMICAL MANAGEMENT UNIT | LICENCE & CERTIFICATE FORM
A2: Yellow cells are inputs. * = required. To edit: type the ID in row 5 and click Find, change fields, then click Update. Leave the ID blank and click Save New for a new record.
B4: FORM STATUS | C4: =IF(IF(C6="","Company; ","")&IF(C7="","Licence Category; ","")&IF(C8="","Licence / Certificate Type; ","")&IF(AND(C6<>"",COUNTIF(Companies!$B$5:$B$74,C6)=0),"Company not in register; ","")="","✔ Ready to save","✖ Missing: "&IF(C6="","Company; ","")&IF(C7="","Licence Category; ","")&IF(C8="","Licence / Certificate Type; ","")&IF(AND(C6<>"",COUNTIF(Companies!$B$5:$B$74,C6)=0),"Company not in register; ","")) -> ✖ Missing: Company; Licence Category; Licence / Certificate Type;
B5: Record ID | D5: {="Leave blank for a NEW record (next ID: "&"LIC-"&TEXT(SUMPRODUCT(MAX(--MID('Licences & Certificates'!$A$5:$A$73,5,4)))+1,"000")&"). Type an existing ID and click Find to edit."} -> Leave blank for a NEW record (next ID: LIC-071). Type an existing ID and click Find to edit.
B6: Company * | D6: {=IF(C6="","",IFERROR("ID: "&INDEX(Companies!$A$5:$A$74,MATCH(C6,Companies!$B$5:$B$74,0)),"⚠ Not in Company register – add it on the Company Form first"))}
B7: Licence Category * | D7: CRL / CIL / EDL / Dewatering / Fumigation / Transport
B8: Licence / Certificate Type * | D8: Choose the specific licence
B9: Location | D9: Site address
B10: Application Date | D10: dd-mmm-yyyy
B11: Response Date | D11: Date EPA responded
B12: Reference Code | D12: e.g. ED/EPA-01/075/26/RL
B13: Licence / Certificate No. | D13: =IF(C13="","Leave blank if not yet issued (status = Pending)",IF(COUNTIF('Licences & Certificates'!$K$5:$K$73,C13)>0,"⚠ This number already exists in the register","✔ Number not used before")) -> Leave blank if not yet issued (status = Pending)
B14: Date Issued | D14: dd-mmm-yyyy
B15: Expiry Date | D15: =IF(AND(C14<>"",C15<>"",C15<C14),"⚠ Expiry is before issue date","Usually 31-Dec-2026 for annual licences") -> Usually 31-Dec-2026 for annual licences
B16: Remarks
B18: CHEMICALS ON THIS LICENCE (CRL / CIL) – up to 15 lines, saved with Save New / Update and loaded by Find
B19: No. | C19: Trade or IUPAC Name | D19: EPA Registration No. | E19: Type | F19: Stipulated Qty (CIL) | G19: Unit (CIL) | H19: Consignment Ref. BL/IPD (CIL)
B20: 1
B21: 2
B22: 3
B23: 4
B24: 5
B25: 6
B26: 7
B27: 8
B28: 9
B29: 10
B30: 11
B31: 12
... B34: 15
B35: Lines | C35: =IF(COUNTA(C20:C34)=0,"No chemical lines entered",COUNTA(C20:C34)&" chemical line(s) will be saved with this licence")&IF(AND(COUNTA(C20:C34)>0,ISERROR(SEARCH("(CRL)",C7)),ISERROR(SEARCH("(CIL)",C7)))," ⚠ Category is not CRL or CIL","") -> No chemical lines entered | D35: CRL: Name, EPA Reg. No., Type. CIL: also Qty, Unit, Consignment Ref.
B37: EDL format ▶ | C37: =IF(ISERROR(SEARCH("EDL",C7)),"(only for Effluent Discharge licences)",IF(ISNUMBER(SEARCH("Retention",C8)),"EDL & RETENTION POND → prints on Print EDL RP (all tables below are used)","STANDARD EDL → prints on Print EDL (Retention Pond tables below are not used)"))&" To switch, change Licence / Certificate Type (C8): Effluent Discharge ⇄ Effluent Discharge & Retention Pond" -> (only for Effluent Discharge licences) To switch, change Licence / Certificate Type (C8): Effluent Discharge ⇄ Effluent Discharge & Retention Pond
B38: EFFLUENT DETAILS (EDL) – fill only for Effluent Discharge licences; saved with Save New / Update and loaded by Find
B39: Receiving water | E39: Used in Conditions 1–2 of the printed EDL, e.g. receiving water “the estuary”, volume “10”, discharge point “in a containment tank”.
B40: Max. volume (m³/day)
B41: Discharge point / facility
B43: DISCHARGE LIMITS – up to 20 lines. List ONLY the parameters this licence requires (pick from the list or type your own)
B44: No. | C44: Parameter | D44: Unit | E44: Limit | F44: Sample Type | G44: Testing Schedule | H44: Discharge Stage (Retention Pond only) e.g. Detox Unit I & II to TSF-II
B45: 1
B46: 2
...

Sheet Clearance Form
A1: ERRS – CHEMICAL MANAGEMENT UNIT | CHEMICAL CLEARANCE FORM (MULTI-CHEMICAL)
A2: One clearance = one Clearance No. (automatic) with up to 20 chemicals. Fill the details once, list the chemicals, click Save New. To edit: type the Clearance No., EPA Ref. No. or a CLR- ID in C5 and click Find.
B4: FORM STATUS | C4: {=IF(IF(C6="","Company; ","")&IF(AND(C6<>"",COUNTIF(Companies!$B$5:$B$74,C6)=0),"Company not in register; ","")&IF(C7="","Clearance Date; ","")&IF(SUMPRODUCT(--((C13:C32<>"")+(D13:D32<>"")>0))=0,"at least one chemical line; ","")&IF(SUMPRODUCT(((C13:C32<>"")+(D13:D32<>"")>0)*(((E13:E32="")+(F13:F32=""))>0))>0,"quantity or unit on "&SUMPRODUCT(((C13:C32<>"")+(D13:D32<>"")>0)*(((E13:E32="")+(F13:F32=""))>0))&" line(s); ","")&IF(SUMPRODUCT((1-((C13:C32<>"")+(D13:D32<>"")>0))*(((E13:E32<>"")+(F13:F32<>""))>0))>0,"chemical name on "&SUMPRODUCT((1-((C13:C32<>"")+(D13:D32<>"")>0))*(((E13:E32<>"")+(F13:F32<>""))>0))&" line(s); ","")&IF(SUMPRODUCT((E13:E32<>"")*NOT(ISNUMBER(E13:E32)))>0,"quantity not a number on "&SUMPRODUCT((E13:E32<>"")*NOT(ISNUMBER(E13:E32)))&" line(s); ","")="","✔ Ready to save – "&SUMPRODUCT(--((C13:C32<>"")+(D13:D32<>"")>0))&" chemical line(s)","✖ Missing: "&IF(C6="","Company; ","")&IF(AND(C6<>"",COUNTIF(Companies!$B$5:$B$74,C6)=0),"Company not in register; ","")&IF(C7="","Clearance Date; ","")&IF(SUMPRODUCT(--((C13:C32<>"")+(D13:D32<>"")>0))=0,"at least one chemical line; ","")&IF(SUMPRODUCT(((C13:C32<>"")+(D13:D32<>"")>0)*(((E13:E32="")+(F13:F32=""))>0))>0,"quantity or unit on "&SUMPRODUCT(((C13:C32<>"")+(D13:D32<>"")>0)*(((E13:E32="")+(F13:F32=""))>0))&" line(s); ","")&IF(SUMPRODUCT((1-((C13:C32<>"")+(D13:D32<>"")>0))*(((E13:E32<>"")+(F13:F32<>""))>0))>0,"chemical name on "&SUMPRODUCT((1-((C13:C32<>"")+(D13:D32<>"")>0))*(((E13:E32<>"")+(F13:F32<>""))>0))&" line(s); ","")&IF(SUMPRODUCT((E13:E32<>"")*NOT(ISNUMBER(E13:E32)))>0,"quantity not a number on "&SUMPRODUCT((E13:E32<>"")*NOT(ISNUMBER(E13:E32)))&" line(s); ",""))} -> ✖ Missing: Company; Clearance Date; at least one chemical line;
B5: Clearance No. | D5: {=IF(C5="","AUTO – leave blank for a new clearance (next: CLN-"&TEXT(MAX(IFERROR(--MID('Chemical Clearances'!$B$5:$B$169,5,4),0))+1,"000")&"). To edit, type a Clearance No. / EPA Ref. / CLR- ID and click Find.",IF(COUNTA(H13:H32)>0,"Loaded "&COUNTA(H13:H32)&" saved line(s) – edit, then click Update","Click Find by ID to load this clearance"))} -> AUTO – leave blank for a new clearance (next: CLN-148). To edit, type a Clearance No. / EPA Ref. / CLR- ID and click Find.
B6: Company * | D6: {=IF(C6="","Choose the company",IFERROR("ID: "&INDEX(Companies!$A$5:$A$74,MATCH(C6,Companies!$B$5:$B$74,0)),"⚠ Not in Company register – add it on the Company Form first"))} -> Choose the company
B7: Clearance Date * | D7: dd-mmm-yyyy
B8: EPA Ref. No. | D8: =IF(OR(C8="",COUNTA(H13:H32)>0),"EPA letter number, e.g. ED/EPA-01/388/26/RL (optional)",IF(COUNTIF('Chemical Clearances'!$L$5:$L$169,C8)>0,"⚠ This EPA Ref. No. is already in the register – check for duplicate","✔ New ref. no.")) -> EPA letter number, e.g. ED/EPA-01/388/26/RL (optional)
B9: B/L / Invoice / AWB No. | D9: =IF(OR(C9="",COUNTA(H13:H32)>0),"Default B/L for all lines – type a different one on a line in column G if needed",IF(COUNTIF('Chemical Clearances'!$K$5:$K$169,C9)>0,"⚠ This B/L is already in the register – check for duplicate","✔ New B/L")) -> Default B/L for all lines – type a different one on a line in column G if needed
B10: Remarks | D10: Applies to all lines
B11: ETA | D11: Estimated arrival – date or text (e.g. N/A). Printed on the clearance letter.
B12: Line | C12: Chemical as Recorded | D12: Chemical (Standard) | E12: Quantity * | F12: Unit * | G12: B/L / Invoice No. (blank = same as C9) | H12: Record ID
B13: 1
B14: 2
B15: 3
B16: 4
B17: 5
B18: 6
B19: 7
B20: 8
B21: 9
B22: 10
B23: 11
B24: 12
... B32: 20
F33: TOTAL kg | G33: {=SUMPRODUCT(--ISNUMBER(E13:E32),N(+E13:E32),(F13:F32="kg")+(F13:F32="MT")*1000)} -> 0 | H33: =TEXT(G33/1000,"#,##0.000")&" MT" -> 0.000 MT
B35: Tip: if Chemical as Recorded is blank, the Standard name is saved in its place. To remove a saved chemical, Find it, clear that whole line (C to F), then click Update.

Sheet Bill Form
A1: ERRS – CHEMICAL MANAGEMENT UNIT | BILL / INVOICE FORM (MULTI-SERVICE)
A2: One bill = one Bill No. (automatic) with up to 10 services. Fill the bill details once, list the services and type each amount, click Save New. To edit: type the Bill No., Bill Ref. No. or a BIL- line ID in C5 and click Find.
B4: FORM STATUS | C4: {=IF(IF(C6="","Company; ","")&IF(AND(C6<>"",COUNTIF(Companies!$B$5:$B$74,C6)=0),"Company not in register; ","")&IF(C7="","Bill Date; ","")&IF(C8="","Bill Type; ","")&IF(AND(C8<>"",SUMPRODUCT((C17:C26<>"")*(COUNTIFS('Fee Schedule'!$A$6:$A$16,C17:C26,'Fee Schedule'!$B$6:$B$16,IFERROR(INDEX('Fee Schedule'!$B$20:$B$26,MATCH(C8,'Fee Schedule'!$A$20:$A$26,0)),"#"))=0))>0),"services not allowed for this Bill Type; ","")&IF(COUNTA(C17:C26)=0,"at least one service line; ","")&IF(SUMPRODUCT((C17:C26<>"")*(E17:E26=""))>0,"amount on "&SUMPRODUCT((C17:C26<>"")*(E17:E26=""))&" line(s); ","")&IF(SUMPRODUCT((C17:C26="")*(E17:E26<>""))>0,"service on "&SUMPRODUCT((C17:C26="")*(E17:E26<>""))&" line(s); ","")&IF(SUMPRODUCT((E17:E26<>"")*NOT(ISNUMBER(E17:E26)))>0,"amount not a number; ","")="","✔ Ready to save – "&C8&" bill, "&COUNTA(C17:C26)&" line(s), total $"&TEXT(SUM(E17:E26),"#,##0.00"),"✖ Missing: "&IF(C6="","Company; ","")&IF(AND(C6<>"",COUNTIF(Companies!$B$5:$B$74,C6)=0),"Company not in register; ","")&IF(C7="","Bill Date; ","")&IF(C8="","Bill Type; ","")&IF(AND(C8<>"",SUMPRODUCT((C17:C26<>"")*(COUNTIFS('Fee Schedule'!$A$6:$A$16,C17:C26,'Fee Schedule'!$B$6:$B$16,IFERROR(INDEX('Fee Schedule'!$B$20:$B$26,MATCH(C8,'Fee Schedule'!$A$20:$A$26,0)),"#"))=0))>0),"services not allowed for this Bill Type; ","")&IF(COUNTA(C17:C26)=0,"at least one service line; ","")&IF(SUMPRODUCT((C17:C26<>"")*(E17:E26=""))>0,"amount on "&SUMPRODUCT((C17:C26<>"")*(E17:E26=""))&" line(s); ","")&IF(SUMPRODUCT((C17:C26="")*(E17:E26<>""))>0,"service on "&SUMPRODUCT((C17:C26="")*(E17:E26<>""))&" line(s); ","")&IF(SUMPRODUCT((E17:E26<>"")*NOT(ISNUMBER(E17:E26)))>0,"amount not a number; ",""))} -> ✖ Missing: Company; Bill Date; Bill Type; at least one service line;
B5: Bill No. | D5: {=IF(C5="","AUTO – leave blank for a new bill (next: BN-"&TEXT(MAX(IFERROR(--MID('Bills & Invoices'!$B$5:$B$32,4,4),0))+1,"000")&"). To edit, type a Bill No. / Bill Ref. No. / BIL- ID and click Find.",IF(COUNTA(G17:G26)>0,"Loaded "&COUNTA(G17:G26)&" saved line(s) – edit, then click Update","Click Find by ID to load this bill"))} -> AUTO – leave blank for a new bill (next: BN-2027). To edit, type a Bill No. / Bill Ref. No. / BIL- ID and click Find.
B6: Company * | D6: {=IF(C6="","Choose the company",IFERROR("ID: "&INDEX(Companies!$A$5:$A$74,MATCH(C6,Companies!$B$5:$B$74,0)),"⚠ Not in Company register – add it on the Company Form first"))} -> Choose the company
B7: Bill Date * | D7: dd-mmm-yyyy
B8: Bill Type * | D8: {=IF(C8="","Choose the Bill Type first – it decides the allowed services and the exact letter wording",IF(SUMPRODUCT((C17:C26<>"")*(COUNTIFS('Fee Schedule'!$A$6:$A$16,C17:C26,'Fee Schedule'!$B$6:$B$16,IFERROR(INDEX('Fee Schedule'!$B$20:$B$26,MATCH(C8,'Fee Schedule'!$A$20:$A$26,0)),"#"))=0))>0,"⚠ "&SUMPRODUCT((C17:C26<>"")*(COUNTIFS('Fee Schedule'!$A$6:$A$16,C17:C26,'Fee Schedule'!$B$6:$B$16,IFERROR(INDEX('Fee Schedule'!$B$20:$B$26,MATCH(C8,'Fee Schedule'!$A$20:$A$26,0)),"#"))=0))&" line(s) are not allowed on a "&C8&" bill – change them or make a separate bill","✔ Letter: "&C8&" wording (see Fee Schedule)"))} -> Choose the Bill Type first – it decides the allowed services and the exact letter wording
B9: Bill Ref. No. | D9: =IF(OR(C9="",COUNTA(G17:G26)>0),"EPA letter reference, e.g. ED/EPA-01/03336/26/RL",IF(COUNTIF('Bills & Invoices'!$P$5:$P$32,C9)>0,"⚠ This Bill Ref. No. is already used – check for duplicate","✔ New reference")) -> EPA letter reference, e.g. ED/EPA-01/03336/26/RL
B10: Contact Person | D10: Name as it should appear, e.g. Mr. Isaac Bestman (or just Isaac Bestman)
B11: Position / Title | D11: Job title, e.g. General Manager, CEO – or Mr./Mrs./Dr. if you typed only the name above
B12: Location | D12: {=IF(C12<>"","",IFERROR("Leave blank to use: "&INDEX(Companies!$D$5:$D$74,MATCH(C6,Companies!$B$5:$B$74,0)),""))}
B13: Activity
B14: Linked Record(s) | D14: Filled by 'Create Bill' (LIC-### / CLN-###) – links this bill to the licence or clearance
B15: BILL LINES (up to 10 services)
B16: Line | C16: Service * | D16: Details / Chemical(s) | E16: Amount (USD) * | F16: Suggested fee | G16: Line ID
B17: 1 | F17: {=IF(C17="","",IFERROR(IF(INDEX('Fee Schedule'!$C$6:$C$16,MATCH(C17,'Fee Schedule'!$A$6:$A$16,0))="","case by case",INDEX('Fee Schedule'!$C$6:$C$16,MATCH(C17,'Fee Schedule'!$A$6:$A$16,0))),""))}
B18: 2 | F18: {=IF(C18="","",IFERROR(IF(INDEX('Fee Schedule'!$C$6:$C$16,MATCH(C18,'Fee Schedule'!$A$6:$A$16,0))="","case by case",INDEX('Fee Schedule'!$C$6:$C$16,MATCH(C18,'Fee Schedule'!$A$6:$A$16,0))),""))}
B19: 3 | F19: {=IF(C19="","",IFERROR(IF(INDEX('Fee Schedule'!$C$6:$C$16,MATCH(C19,'Fee Schedule'!$A$6:$A$16,0))="","case by case",INDEX('Fee Schedule'!$C$6:$C$16,MATCH(C19,'Fee Schedule'!$A$6:$A$16,0))),""))}
B20: 4 | F20: {=IF(C20="","",IFERROR(IF(INDEX('Fee Schedule'!$C$6:$C$16,MATCH(C20,'Fee Schedule'!$A$6:$A$16,0))="","case by case",INDEX('Fee Schedule'!$C$6:$C$16,MATCH(C20,'Fee Schedule'!$A$6:$A$16,0))),""))}
B21: 5 | F21: {=IF(C21="","",IFERROR(IF(INDEX('Fee Schedule'!$C$6:$C$16,MATCH(C21,'Fee Schedule'!$A$6:$A$16,0))="","case by case",INDEX('Fee Schedule'!$C$6:$C$16,MATCH(C21,'Fee Schedule'!$A$6:$A$16,0))),""))}
B22: 6 | F22: {=IF(C22="","",IFERROR(IF(INDEX('Fee Schedule'!$C$6:$C$16,MATCH(C22,'Fee Schedule'!$A$6:$A$16,0))="","case by case",INDEX('Fee Schedule'!$C$6:$C$16,MATCH(C22,'Fee Schedule'!$A$6:$A$16,0))),""))}
B23: 7 | F23: {=IF(C23="","",IFERROR(IF(INDEX('Fee Schedule'!$C$6:$C$16,MATCH(C23,'Fee Schedule'!$A$6:$A$16,0))="","case by case",INDEX('Fee Schedule'!$C$6:$C$16,MATCH(C23,'Fee Schedule'!$A$6:$A$16,0))),""))}
B24: 8 | F24: {=IF(C24="","",IFERROR(IF(INDEX('Fee Schedule'!$C$6:$C$16,MATCH(C24,'Fee Schedule'!$A$6:$A$16,0))="","case by case",INDEX('Fee Schedule'!$C$6:$C$16,MATCH(C24,'Fee Schedule'!$A$6:$A$16,0))),""))}
B25: 9 | F25: {=IF(C25="","",IFERROR(IF(INDEX('Fee Schedule'!$C$6:$C$16,MATCH(C25,'Fee Schedule'!$A$6:$A$16,0))="","case by case",INDEX('Fee Schedule'!$C$6:$C$16,MATCH(C25,'Fee Schedule'!$A$6:$A$16,0))),""))}
B26: 10 | F26: {=IF(C26="","",IFERROR(IF(INDEX('Fee Schedule'!$C$6:$C$16,MATCH(C26,'Fee Schedule'!$A$6:$A$16,0))="","case by case",INDEX('Fee Schedule'!$C$6:$C$16,MATCH(C26,'Fee Schedule'!$A$6:$A$16,0))),""))}
D27: TOTAL | E27: =SUM(E17:E26) -> 0
B29: Company account | C29: {=IF(C6="","",IFERROR("Billed $"&TEXT(SUMIFS('Bills & Invoices'!$J$5:$J$32,'Bills & Invoices'!$C$5:$C$32,INDEX(Companies!$A$5:$A$74,MATCH(C6,Companies!$B$5:$B$74,0))),"#,##0")&" | Paid $"&TEXT(SUMIFS('Payments & Receipts'!$F$5:$F$58,'Payments & Receipts'!$B$5:$B$58,INDEX(Companies!$A$5:$A$74,MATCH(C6,Companies!$B$5:$B$74,0))),"#,##0")&" | Outstanding $"&TEXT(MAX(0,SUMIFS('Bills & Invoices'!$J$5:$J$32,'Bills & Invoices'!$C$5:$C$32,INDEX(Companies!$A$5:$A$74,MATCH(C6,Companies!$B$5:$B$74,0)))-SUMIFS('Payments & Receipts'!$F$5:$F$58,'Payments & Receipts'!$B$5:$B$58,INDEX(Companies!$A$5:$A$74,MATCH(C6,Companies!$B$5:$B$74,0)))),"#,##0"),""))}
B31: Tip: to remove a saved service from a bill, Find the bill, clear that line's Service and Amount, then click Update.

Sheet Payment Form
A1: ERRS – CHEMICAL MANAGEMENT UNIT | PAYMENT / RECEIPT FORM
A2: Yellow cells are inputs. * = required. To edit: type the ID in row 5 and click Find, change fields, then click Update. Leave the ID blank and click Save New for a new record.
B4: FORM STATUS | C4: =IF(IF(C6="","Company; ","")&IF(C7="","Purpose / Services; ","")&IF(C8="","Amount (USD); ","")&IF(C9="","Payment Date; ","")&IF(AND(C6<>"",COUNTIF(Companies!$B$5:$B$74,C6)=0),"Company not in register; ","")&IF(AND(C8<>"",NOT(ISNUMBER(C8))),"Amount (USD) not a number; ","")="","✔ Ready to save","✖ Missing: "&IF(C6="","Company; ","")&IF(C7="","Purpose / Services; ","")&IF(C8="","Amount (USD); ","")&IF(C9="","Payment Date; ","")&IF(AND(C6<>"",COUNTIF(Companies!$B$5:$B$74,C6)=0),"Company not in register; ","")&IF(AND(C8<>"",NOT(ISNUMBER(C8))),"Amount (USD) not a number; ","")) -> ✖ Missing: Company; Purpose / Services; Amount (USD); Payment Date;
B5: Record ID | D5: {="Leave blank for a NEW record (next ID: "&"PAY-"&TEXT(SUMPRODUCT(MAX(--MID('Payments & Receipts'!$A$5:$A$58,5,4)))+1,"000")&"). Type an existing ID and click Find to edit."} -> Leave blank for a NEW record (next ID: PAY-055). Type an existing ID and click Find to edit.
B6: Company * | D6: {=IF(C6="","",IFERROR("ID: "&INDEX(Companies!$A$5:$A$74,MATCH(C6,Companies!$B$5:$B$74,0)),"⚠ Not in Company register – add it on the Company Form first"))}
B7: Purpose / Services * | D7: What the payment is for
B8: Amount (USD) * | D8: US dollars
B9: Payment Date * | D9: dd-mmm-yyyy
B10: Receipt No. | D10: =IF(C10="","Receipt number from the payment slip",IF(COUNTIF('Payments & Receipts'!$H$5:$H$58,C10)>0,"⚠ Receipt already recorded – check for duplicate","✔ New receipt")) -> Receipt number from the payment slip
B11: Remarks
B12: Bill No. (paying for) | D12: {=IF(C12="","Link this payment to a bill so the bill shows Paid / Part paid",IFERROR(INDEX('Bills & Invoices'!$D$5:$D$32,MATCH(C12,'Bills & Invoices'!$B$5:$B$32,0))&": billed $"&TEXT(SUMIFS('Bills & Invoices'!$J$5:$J$32,'Bills & Invoices'!$B$5:$B$32,C12),"#,##0.00")&", paid $"&TEXT(SUMIFS('Payments & Receipts'!$F$5:$F$58,'Payments & Receipts'!$L$5:$L$58,C12),"#,##0.00")&IF(AND(C6<>"",INDEX('Bills & Invoices'!$D$5:$D$32,MATCH(C12,'Bills & Invoices'!$B$5:$B$32,0))<>C6)," ⚠ bill belongs to another company",""),"⚠ Bill not found"))} -> Link this payment to a bill so the bill shows Paid / Part paid
B13: Company account | C13: {=IF(C6="","",IFERROR("Billed $"&TEXT(SUMIFS('Bills & Invoices'!$J$5:$J$32,'Bills & Invoices'!$C$5:$C$32,INDEX(Companies!$A$5:$A$74,MATCH(C6,Companies!$B$5:$B$74,0))),"#,##0")&" | Paid $"&TEXT(SUMIFS('Payments & Receipts'!$F$5:$F$58,'Payments & Receipts'!$B$5:$B$58,INDEX(Companies!$A$5:$A$74,MATCH(C6,Companies!$B$5:$B$74,0))),"#,##0")&" | Outstanding $"&TEXT(MAX(0,SUMIFS('Bills & Invoices'!$J$5:$J$32,'Bills & Invoices'!$C$5:$C$32,INDEX(Companies!$A$5:$A$74,MATCH(C6,Companies!$B$5:$B$74,0)))-SUMIFS('Payments & Receipts'!$F$5:$F$58,'Payments & Receipts'!$B$5:$B$58,INDEX(Companies!$A$5:$A$74,MATCH(C6,Companies!$B$5:$B$74,0)))),"#,##0"),""))}

Sheet Print CRL
B2: =IF($J$3="No","",setLetterhead_1) -> REPUBLIC OF LIBERIA | I2: PRINT – ANNUAL CHEMICAL REGISTRATION LICENSE
B3: =IF($J$3="No","",setLetterhead_2) -> ENVIRONMENTAL PROTECTION AGENCY | I3: Print letterhead ▶ | J3: Yes
B4: =IF($J$3="No","",setLetterhead_3) -> P.O. Box 4024 | I4: Licence Record ID ▶
B5: =IF($J$3="No","",setLetterhead_4) -> Bright Building 302-A, Sekou Toure Avenue, Mamba Point | I5: Check | J5: {=IF($J$4="","Choose a licence record",IF($J$6="","⚠ Record not found",IF(ISNUMBER(SEARCH("CRL",INDEX('Licences & Certificates'!$E$5:$E$73,$J$6))),IF(INDEX('Licences & Certificates'!$K$5:$K$73,$J$6)="","⚠ No licence number yet","✔ Ready to print"),"⚠ This record is "&INDEX('Licences & Certificates'!$E$5:$E$73,$J$6))))} -> Choose a licence record
B6: =IF($J$3="No","",setLetterhead_5) -> 1000 Monrovia, 10 Liberia | I6: (row in register) | J6: =IFERROR(MATCH($J$4,'Licences & Certificates'!$A$5:$A$73,0),"")
I7: Licence No. | J7: {=IF($J$6="","",INDEX('Licences & Certificates'!$K$5:$K$73,$J$6)&"")}
I8: Company | J8: {=IF($J$6="","",INDEX('Licences & Certificates'!$C$5:$C$73,$J$6))}
B9: =IF($J$7="","License No. ________","License No. "&$J$7) -> License No. ________ | I9: Location | J9: {=IF($J$6="","",IF(INDEX('Licences & Certificates'!$G$5:$G$73,$J$6)<>"",INDEX('Licences & Certificates'!$G$5:$G$73,$J$6),IFERROR(INDEX(Companies!$D$5:$D$74,MATCH(INDEX('Licences & Certificates'!$B$5:$B$73,$J$6),Companies!$A$5:$A$74,0))&"","")))}
I10: Date Issued | J10: {=IF($J$6="","",IF(INDEX('Licences & Certificates'!$L$5:$L$73,$J$6)="","",INDEX('Licences & Certificates'!$L$5:$L$73,$J$6)))}
B11: ANNUAL CHEMICAL REGISTRATION LICENSE | I11: Expiry Date | J11: {=IF($J$6="","",IF(INDEX('Licences & Certificates'!$M$5:$M$73,$J$6)="","",INDEX('Licences & Certificates'!$M$5:$M$73,$J$6)))}
B12: (Issued under Part II Section VI of the EPA Act) | I12: Chemical lines found | J12: =COUNTIF('Licence Chemicals'!$A$5:$A$167,$J$4) -> 0
I13: Signed by ▶ | J13: Executive Director
B14: This is to certify that | I14: How to use: pick the Licence Record ID in J4 and choose who signs. Add the chemicals for that licence on the 'Licence Chemicals' sheet. Then use the OUTPUT buttons on the right – empty table rows are left out automatically. Set 'Print letterhead' (J3) to No when printing on pre-printed EPA letterhead paper – the letterhead text and logos are left off, keeping the same space at the top.
B15: =UPPER($J$8)
B16: =IF($J$9="","","(Located at "&$J$9&")")
B18: Is hereby granted this Annual Chemical Registration License, pursuant to Part 5 Section 51-53 of the Environmental Protection and Management Law of Liberia and Section 5.5 & 5.6 of the National Environmental Policy of Liberia, for the registration of Industrial Chemicals, subject to the EPA Act, the Chemical Guideline of Liberia and conditions specified in this license.
B20: PRODUCT INFORMATION
B21: No. | C21: Trade or IUPAC Name | D21: EPA Registration #. | E21: Types | L21: helper
B22: =IF($L22="","",ROWS($L$22:L22)) | C22: {=IF($L22="","",INDEX('Licence Chemicals'!$D$5:$D$167,$L22)&"")} | D22: {=IF($L22="","",INDEX('Licence Chemicals'!$E$5:$E$167,$L22)&"")} | E22: {=IF($L22="","",IF(INDEX('Licence Chemicals'!$F$5:$F$167,$L22)="","Industrial Chemical",INDEX('Licence Chemicals'!$F$5:$F$167,$L22)&""))} | L22: =IFERROR(__xludf.DUMMYFUNCTION("ARRAY_CONSTRAIN(ARRAYFORMULA(IFERROR(SMALL(FILTER((ROW('Licence Chemicals'!$A$5:$A$167)-ROW('Licence Chemicals'!$A$4:$I$4)),IFERROR(('Licence Chemicals'!$A$5:$A$167=$J$4),FALSE)),ROWS($L$22:L22)),"""")), 1, 1)"),"")
B23: =IF($L23="","",ROWS($L$22:L23)) | C23: {=IF($L23="","",INDEX('Licence Chemicals'!$D$5:$D$167,$L23)&"")} | D23: {=IF($L23="","",INDEX('Licence Chemicals'!$E$5:$E$167,$L23)&"")} | E23: {=IF($L23="","",IF(INDEX('Licence Chemicals'!$F$5:$F$167,$L23)="","Industrial Chemical",INDEX('Licence Chemicals'!$F$5:$F$167,$L23)&""))} | L23: =IFERROR(__xludf.DUMMYFUNCTION("ARRAY_CONSTRAIN(ARRAYFORMULA(IFERROR(SMALL(FILTER((ROW('Licence Chemicals'!$A$5:$A$167)-ROW('Licence Chemicals'!$A$4:$I$4)),IFERROR(('Licence Chemicals'!$A$5:$A$167=$J$4),FALSE)),ROWS($L$22:L23)),"""")), 1, 1)"),"")
B24: =IF($L24="","",ROWS($L$22:L24)) | C24: {=IF($L24="","",INDEX('Licence Chemicals'!$D$5:$D$167,$L24)&"")} | D24: {=IF($L24="","",INDEX('Licence Chemicals'!$E$5:$E$167,$L24)&"")} | E24: {=IF($L24="","",IF(INDEX('Licence Chemicals'!$F$5:$F$167,$L24)="","Industrial Chemical",INDEX('Licence Chemicals'!$F$5:$F$167,$L24)&""))} | L24: =IFERROR(__xludf.DUMMYFUNCTION("ARRAY_CONSTRAIN(ARRAYFORMULA(IFERROR(SMALL(FILTER((ROW('Licence Chemicals'!$A$5:$A$167)-ROW('Licence Chemicals'!$A$4:$I$4)),IFERROR(('Licence Chemicals'!$A$5:$A$167=$J$4),FALSE)),ROWS($L$22:L24)),"""")), 1, 1)"),"")
