Workbook
Name CountyList: Reference!$A$26:$A$37
Name MediumList: Reference!$C$26:$C$29
Name ParameterList: Reference!$D$26:$D$42
Name ComplaintTypeList: Reference!$E$26:$E$31
Name ComplaintStatusList: Reference!$F$26:$F$29
Name SeverityList: Reference!$G$26:$G$29
Name FacilityTypeList: Reference!$H$26:$H$31
Name RadFacilityTypeList: Reference!$I$26:$I$28
Name SourceTypeList: Reference!$J$26:$J$41
Name OutcomeList: Reference!$K$26:$K$28
Name YesNoList: Reference!$L$26:$L$27

Sheet Dashboard
B1: Environmental & Public Health Dashboard
B2: Liberia Environmental Protection Agency | Environmental Research & Radiation Safety (ERRS) Department | Reporting period: January - August 2026 | Sample data - replace with real records
B5: SAMPLES TESTED | E5: WITHIN SAFETY LIMITS | H5: EXCEEDANCES DETECTED | K5: POPULATION SERVED
B6: =CalcData!$B$93 -> 536 | E6: =CalcData!$B$96 -> 0.80597015 | H6: =CalcData!$B$95 -> 104 | K6: =CalcData!$B$97 -> 683050
B7: Environmental samples analysed against a safety limit | E7: Share of samples at or below the WHO / IAEA guideline applied | H7: Results above the applicable safety limit | K7: People relying on the water sources and sites monitored
B10: ILLNESS CASES REPORTED | E10: COMPLAINTS STILL OPEN | H10: AVG DAYS TO RESOLVE | K10: FACILITY COMPLIANCE
B11: =CalcData!$B$98 -> 1161 | E11: =CalcData!$B$100 -> 46 | H11: =CalcData!$B$102 -> 19.508475 | K11: =CalcData!$B$104 -> 0.6097561
B12: Cases linked to an environmental health complaint | E12: Received, investigating, or awaiting findings | H12: Average time from receipt to closure | K12: Inspected facilities found compliant on the day
B15: RADIATION FACILITIES | E15: AVG OCCUPATIONAL DOSE | H15: HIGH / CRITICAL COMPLAINTS | K15: WATER EXCEEDANCE RATE
B16: =CalcData!$B$106 -> 42 | E16: =CalcData!$B$107 -> 6.8595238 | H16: =CalcData!$B$101 -> 33 | K16: =CalcData!$B$105 -> 0.19148936
B17: Licensed facilities holding radioactive sources | E17: Per monitored worker, against the 20 mSv annual limit | H17: Complaints graded High or Critical by illness burden | K17: Share of water samples above limit - the headline exposure risk
B21: Trends and breakdowns

Sheet Lab Results
A1: Laboratory Results - Environmental Health Sampling
A2: One row per sample. 'Within Limit' and 'Exceedance Ratio' are formulas - type a new Result or change a limit and they update themselves.
A3: Sample ID | B3: Sample Date | C3: Month | D3: County | E3: Community / Site | F3: Source Type | G3: Medium | H3: Parameter | I3: Result | J3: Unit | K3: Limit Min | L3: Limit Max | M3: Within Limit | N3: Exceedance Ratio | O3: Population Served | P3: Nearest Health Facility | Q3: Analyst
A4: AQ-2026-00001 | B4: 46037 | C4: =MONTH(B4) -> 1 | D4: Bong | E4: Maryland Oil Palm Estate | F4: Industrial Perimeter | G4: Air | H4: PM2.5 | I4: 18.5 | J4: ug/m3 | K4: 0 | L4: 25 | M4: =IF(AND(I4>=K4,I4<=L4),"Yes","No") -> Yes | N4: =IF(L4=0,"",I4/L4) -> 0.74 | O4: 200 | P4: Suakoko Clinic | Q4: J. Nyeman
A5: WQ-2026-00002 | B5: 46043 | C5: =MONTH(B5) -> 1 | D5: Montserrado | E5: Caldwell - River / Stream Intake | F5: River / Stream Intake | G5: Water | H5: Total Coliform | I5: 0 | J5: CFU/100 mL | K5: 0 | L5: 0 | M5: =IF(AND(I5>=K5,I5<=L5),"Yes","No") -> Yes | N5: =IF(L5=0,"",I5/L5) | O5: 1800 | P5: Benson Hospital | Q5: J. Nyeman
A6: WQ-2026-00003 | B6: 46027 | C6: =MONTH(B6) -> 1 | D6: Bong | E6: Salala - River / Stream Intake | F6: River / Stream Intake | G6: Water | H6: Lead | I6: 0.0133 | J6: mg/L | K6: 0 | L6: 0.01 | M6: =IF(AND(I6>=K6,I6<=L6),"Yes","No") -> No | N6: =IF(L6=0,"",I6/L6) -> 1.33 | O6: 750 | P6: Gbarnga Health Center | Q6: S. Dolo
A7: WQ-2026-00004 | B7: 46047 | C7: =MONTH(B7) -> 1 | D7: Montserrado | E7: Gardnersville - Community Borehole | F7: Community Borehole | G7: Water | H7: Nitrate (as NO3) | I7: 3.3 | J7: mg/L | K7: 0 | L7: 10 | M7: =IF(AND(I7>=K7,I7<=L7),"Yes","No") -> Yes | N7: =IF(L7=0,"",I7/L7) -> 0.33 | O7: 2500 | P7: Redemption Hospital | Q7: T. Mulbah
A8: SL-2026-00005 | B8: 46035 | C8: =MONTH(B8) -> 1 | D8: Montserrado | E8: Caldwell - Playground | F8: Playground | G8: Soil | H8: Cadmium | I8: 1.2 | J8: mg/kg | K8: 0 | L8: 3 | M8: =IF(AND(I8>=K8,I8<=L8),"Yes","No") -> Yes | N8: =IF(L8=0,"",I8/L8) -> 0.4 | O8: 0 | P8: St. Joseph's Catholic Hospital | Q8: A. Kollie
A9: WQ-2026-00006 | B9: 46028 | C9: =MONTH(B9) -> 1 | D9: Montserrado | E9: Caldwell - Community Borehole | F9: Community Borehole | G9: Water | H9: Arsenic | I9: 0.0077 | J9: mg/L | K9: 0 | L9: 0.01 | M9: =IF(AND(I9>=K9,I9<=L9),"Yes","No") -> Yes | N9: =IF(L9=0,"",I9/L9) -> 0.77 | O9: 900 | P9: Redemption Hospital | Q9: B. Kpadeh
A10: RD-2026-00007 | B10: 46042 | C10: =MONTH(B10) -> 1 | D10: Montserrado | E10: West Point - Urban Background | F10: Urban Background | G10: Ambient Radiation | H10: Gamma Dose Rate | I10: 0.12 | J10: uSv/h | K10: 0 | L10: 0.3 | M10: =IF(AND(I10>=K10,I10<=L10),"Yes","No") -> Yes | N10: =IF(L10=0,"",I10/L10) -> 0.4 | O10: 0 | P10: JFK Memorial Hospital | Q10: J. Nyeman
A11: WQ-2026-00008 | B11: 46028 | C11: =MONTH(B11) -> 1 | D11: Grand Bassa | E11: St. John River - Community Borehole | F11: Community Borehole | G11: Water | H11: Arsenic | I11: 0.0042 | J11: mg/L | K11: 0 | L11: 0.01 | M11: =IF(AND(I11>=K11,I11<=L11),"Yes","No") -> Yes | N11: =IF(L11=0,"",I11/L11) -> 0.42 | O11: 350 | P11: Buchanan Government Hospital | Q11: F. Gbato
A12: WQ-2026-00009 | B12: 46032 | C12: =MONTH(B12) -> 1 | D12: Sinoe | E12: Butaw - School Water Point | F12: School Water Point | G12: Water | H12: Lead | I12: 0.0048 | J12: mg/L | K12: 0 | L12: 0.01 | M12: =IF(AND(I12>=K12,I12<=L12),"Yes","No") -> Yes | N12: =IF(L12=0,"",I12/L12) -> 0.48 | O12: 4200 | P12: F.J. Grante Hospital | Q12: A. Kollie
A13: WQ-2026-00010 | B13: 46047 | C13: =MONTH(B13) -> 1 | D13: Grand Bassa | E13: Buchanan - School Water Point | F13: School Water Point | G13: Water | H13: Lead | I13: 0.0003 | J13: mg/L | K13: 0 | L13: 0.01 | M13: =IF(AND(I13>=K13,I13<=L13),"Yes","No") -> Yes | N13: =IF(L13=0,"",I13/L13) -> 0.03 | O13: 500 | P13: Buchanan Government Hospital | Q13: T. Mulbah
A14: WQ-2026-00011 | B14: 46033 | C14: =MONTH(B14) -> 1 | D14: Nimba | E14: Yekepa - School Water Point | F14: School Water Point | G14: Water | H14: Manganese | I14: 0.19 | J14: mg/L | K14: 0 | L14: 0.4 | M14: =IF(AND(I14>=K14,I14<=L14),"Yes","No") -> Yes | N14: =IF(L14=0,"",I14/L14) -> 0.475 | O14: 900 | P14: Ganta United Methodist Hospital | Q14: P. Wleh
A15: WQ-2026-00012 | B15: 46046 | C15: =MONTH(B15) -> 1 | D15: Maryland | E15: Pleebo - Community Borehole | F15: Community Borehole | G15: Water | H15: Turbidity | I15: 12 | J15: NTU | K15: 0 | L15: 5 | M15: =IF(AND(I15>=K15,I15<=L15),"Yes","No") -> No | N15: =IF(L15=0,"",I15/L15) -> 2.4 | O15: 4200 | P15: Harper Hospital | Q15: J. Nyeman
... A539: SL-2026-00536 | B539: 46252 | C539: =MONTH(B539) -> 8 | D539: Grand Bassa | E539: Edina - Farmland | F539: Farmland | G539: Soil | H539: Mercury | I539: 1.3 | J539: mg/kg | K539: 0 | L539: 1 | M539: =IF(AND(I539>=K539,I539<=L539),"Yes","No") -> No | N539: =IF(L539=0,"",I539/L539) -> 1.3 | O539: 200 | P539: Buchanan Government Hospital | Q539: E. Sebo

Sheet Health Complaints
A1: Environmental Health Complaints
A2: One row per complaint. Illness Cases Reported is the health burden the complaint represents; Days to Resolve is calculated from the two date columns.
A3: Complaint ID | B3: Date Received | C3: Month | D3: County | E3: Community | F3: Complaint Type | G3: Description | H3: Illness Cases Reported | I3: Severity | J3: Status | K3: Date Closed | L3: Days to Resolve | M3: Linked to Lab Exceedance | N3: Action Taken
A4: HC-2026-0001 | B4: 46041 | C4: =MONTH(B4) -> 1 | D4: Nimba | E4: Yekepa | F4: Waste Dumping | G4: Unauthorised dumping of mixed and medical waste on vacant land; scavenging by children reported. | H4: 3 | I4: Medium | J4: Investigating | L4: =IF(K4="","",K4-B4) | M4: No | N4: Dumpsite cleared; warning notice served; monthly surveillance added.
A5: HC-2026-0002 | B5: 46036 | C5: =MONTH(B5) -> 1 | D5: Nimba | E5: Saclepea | F5: Drinking Water Contamination | G5: Residents report discoloured water with an odour from the public tap stand; suspected faecal contamination after heavy rain. | H5: 18 | I5: High | J5: Received | L5: =IF(K5="","",K5-B5) | M5: Yes | N5: Water point sampled; chlorination advised; community sensitised on boiling.
A6: HC-2026-0003 | B6: 46044 | C6: =MONTH(B6) -> 1 | D6: Bong | E6: Suakoko | F6: Drinking Water Contamination | G6: Residents report discoloured water with an odour from the public tap stand; suspected faecal contamination after heavy rain. | H6: 12 | I6: High | J6: Closed | K6: 46054 | L6: =IF(K6="","",K6-B6) -> 10 | M6: Yes | N6: Water point sampled; chlorination advised; community sensitised on boiling.
A7: HC-2026-0004 | B7: 46025 | C7: =MONTH(B7) -> 1 | D7: Nimba | E7: Butuo | F7: Waste Dumping | G7: Unauthorised dumping of mixed and medical waste on vacant land; scavenging by children reported. | H7: 6 | I7: Medium | J7: Closed | K7: 46055 | L7: =IF(K7="","",K7-B7) -> 30 | M7: No | N7: Dumpsite cleared; warning notice served; monthly surveillance added.
A8: HC-2026-0005 | B8: 46025 | C8: =MONTH(B8) -> 1 | D8: Grand Bassa | E8: Buchanan | F8: Air Quality / Smoke & Dust | G8: Dust and smoke from open burning of waste; households report coughing and eye irritation. | H8: 14 | I8: High | J8: Received | L8: =IF(K8="","",K8-B8) | M8: No | N8: Air sampling conducted; operator directed to suppress dust and stop open burning.
A9: HC-2026-0006 | B9: 46051 | C9: =MONTH(B9) -> 1 | D9: Grand Cape Mount | E9: Sinje | F9: Air Quality / Smoke & Dust | G9: Dust and smoke from charcoal production; households report coughing and eye irritation. | H9: 2 | I9: Low | J9: Closed | K9: 46055 | L9: =IF(K9="","",K9-B9) -> 4 | M9: No | N9: Air sampling conducted; operator directed to suppress dust and stop open burning.
A10: HC-2026-0007 | B10: 46036 | C10: =MONTH(B10) -> 1 | D10: Nimba | E10: Ganta | F10: Air Quality / Smoke & Dust | G10: Dust and smoke from unpaved haul road; households report coughing and eye irritation. | H10: 9 | I10: Medium | J10: Investigating | L10: =IF(K10="","",K10-B10) | M10: No | N10: Air sampling conducted; operator directed to suppress dust and stop open burning.
A11: HC-2026-0008 | B11: 46027 | C11: =MONTH(B11) -> 1 | D11: Lofa | E11: Zorzor | F11: Waste Dumping | G11: Unauthorised dumping of mixed and medical waste on vacant land; scavenging by children reported. | H11: 1 | I11: Low | J11: Investigating | L11: =IF(K11="","",K11-B11) | M11: No | N11: Dumpsite cleared; warning notice served; monthly surveillance added.
A12: HC-2026-0009 | B12: 46042 | C12: =MONTH(B12) -> 1 | D12: Bong | E12: Totota | F12: Air Quality / Smoke & Dust | G12: Dust and smoke from charcoal production; households report coughing and eye irritation. | H12: 14 | I12: High | J12: Closed | K12: 46061 | L12: =IF(K12="","",K12-B12) -> 19 | M12: No | N12: Air sampling conducted; operator directed to suppress dust and stop open burning.
A13: HC-2026-0010 | B13: 46029 | C13: =MONTH(B13) -> 1 | D13: Montserrado | E13: New Kru Town | F13: Waste Dumping | G13: Unauthorised dumping of mixed and medical waste on vacant land; scavenging by children reported. | H13: 3 | I13: Medium | J13: Investigating | L13: =IF(K13="","",K13-B13) | M13: No | N13: Dumpsite cleared; warning notice served; monthly surveillance added.
A14: HC-2026-0011 | B14: 46041 | C14: =MONTH(B14) -> 1 | D14: Grand Bassa | E14: Edina | F14: Waste Dumping | G14: Unauthorised dumping of mixed and medical waste on vacant land; scavenging by children reported. | H14: 3 | I14: Medium | J14: Closed | K14: 46072 | L14: =IF(K14="","",K14-B14) -> 31 | M14: No | N14: Dumpsite cleared; warning notice served; monthly surveillance added.
A15: HC-2026-0012 | B15: 46030 | C15: =MONTH(B15) -> 1 | D15: Montserrado | E15: Caldwell | F15: Air Quality / Smoke & Dust | G15: Dust and smoke from open burning of waste; households report coughing and eye irritation. | H15: 5 | I15: Medium | J15: Findings Presented | L15: =IF(K15="","",K15-B15) | M15: No | N15: Air sampling conducted; operator directed to suppress dust and stop open burning.
A16: HC-2026-0013 | B16: 46037 | C16: =MONTH(B16) -> 1 | D16: Montserrado | E16: West Point | F16: Sanitation | G16: Overflowing latrine / open defecation near a dwelling; residents report diarrhoeal illness, mostly in children under five. | H16: 3 | I16: Medium | J16: Closed | K16: 46054 | L16: =IF(K16="","",K16-B16) -> 17 | M16: Yes | N16: Referred to county health team; latrine disinfection and clean-up ordered.
A17: HC-2026-0014 | B17: 46052 | C17: =MONTH(B17) -> 1 | D17: Bong | E17: Gbarnga | F17: Air Quality / Smoke & Dust | G17: Dust and smoke from charcoal production; households report coughing and eye irritation. | H17: 30 | I17: Critical | J17: Investigating | L17: =IF(K17="","",K17-B17) | M17: No | N17: Air sampling conducted; operator directed to suppress dust and stop open burning.
A18: HC-2026-0015 | B18: 46063 | C18: =MONTH(B18) -> 2 | D18: Grand Bassa | E18: Edina | F18: Drinking Water Contamination | G18: Residents report discoloured water with an odour from the public tap stand; suspected faecal contamination after heavy rain. | H18: 8 | I18: Medium | J18: Closed | K18: 46082 | L18: =IF(K18="","",K18-B18) -> 19 | M18: Yes | N18: Water point sampled; chlorination advised; community sensitised on boiling.
A19: HC-2026-0016 | B19: 46055 | C19: =MONTH(B19) -> 2 | D19: Montserrado | E19: Paynesville | F19: Noise | G19: Continuous low-frequency noise at night from a generator set. | H19: 2 | I19: Low | J19: Closed | K19: 46069 | L19: =IF(K19="","",K19-B19) -> 14 | M19: No | N19: Noise measurement taken; operator advised on night-time operating hours.
A20: HC-2026-0017 | B20: 46068 | C20: =MONTH(B20) -> 2 | D20: Margibi | E20: Kakata | F20: Sanitation | G20: Overflowing latrine / open defecation near a dwelling; residents report diarrhoeal illness, mostly in children under five. | H20: 11 | I20: Medium | J20: Received | L20: =IF(K20="","",K20-B20) | M20: Yes | N20: Referred to county health team; latrine disinfection and clean-up ordered.
A21: HC-2026-0018 | B21: 46081 | C21: =MONTH(B21) -> 2 | D21: Bong | E21: Suakoko | F21: Drinking Water Contamination | G21: Residents report discoloured water with an odour from the public tap stand; suspected faecal contamination after heavy rain. | H21: 62 | I21: Critical | J21: Investigating | L21: =IF(K21="","",K21-B21) | M21: Yes | N21: Water point sampled; chlorination advised; community sensitised on boiling.
A22: HC-2026-0019 | B22: 46080 | C22: =MONTH(B22) -> 2 | D22: Montserrado | E22: Brewerville | F22: Air Quality / Smoke & Dust | G22: Dust and smoke from clinker handling; households report coughing and eye irritation. | H22: 5 | I22: Medium | J22: Closed | K22: 46101 | L22: =IF(K22="","",K22-B22) -> 21 | M22: No | N22: Air sampling conducted; operator directed to suppress dust and stop open burning.
A23: HC-2026-0020 | B23: 46068 | C23: =MONTH(B23) -> 2 | D23: Grand Cape Mount | E23: Tieni | F23: Air Quality / Smoke & Dust | G23: Dust and smoke from open burning of waste; households report coughing and eye irritation. | H23: 14 | I23: High | J23: Closed | K23: 46072 | L23: =IF(K23="","",K23-B23) -> 4 | M23: No | N23: Air sampling conducted; operator directed to suppress dust and stop open burning.
A24: HC-2026-0021 | B24: 46066 | C24: =MONTH(B24) -> 2 | D24: Montserrado | E24: Sinkor | F24: Air Quality / Smoke & Dust | G24: Dust and smoke from charcoal production; households report coughing and eye irritation. | H24: 9 | I24: Medium | J24: Investigating | L24: =IF(K24="","",K24-B24) | M24: No | N24: Air sampling conducted; operator directed to suppress dust and stop open burning.
A25: HC-2026-0022 | B25: 46058 | C25: =MONTH(B25) -> 2 | D25: Montserrado | E25: Brewerville | F25: Air Quality / Smoke & Dust | G25: Dust and smoke from unpaved haul road; households report coughing and eye irritation. | H25: 5 | I25: Medium | J25: Closed | K25: 46078 | L25: =IF(K25="","",K25-B25) -> 20 | M25: No | N25: Air sampling conducted; operator directed to suppress dust and stop open burning.
A26: HC-2026-0023 | B26: 46055 | C26: =MONTH(B26) -> 2 | D26: Nimba | E26: Saclepea | F26: Waste Dumping | G26: Unauthorised dumping of mixed and medical waste on vacant land; scavenging by children reported. | H26: 6 | I26: Medium | J26: Closed | K26: 46093 | L26: =IF(K26="","",K26-B26) -> 38 | M26: No | N26: Dumpsite cleared; warning notice served; monthly surveillance added.
A27: HC-2026-0024 | B27: 46063 | C27: =MONTH(B27) -> 2 | D27: Margibi | E27: Kakata | F27: Air Quality / Smoke & Dust | G27: Dust and smoke from open burning of waste; households report coughing and eye irritation. | H27: 5 | I27: Medium | J27: Investigating | L27: =IF(K27="","",K27-B27) | M27: No | N27: Air sampling conducted; operator directed to suppress dust and stop open burning.
A28: HC-2026-0025 | B28: 46075 | C28: =MONTH(B28) -> 2 | D28: Montserrado | E28: West Point | F28: Drinking Water Contamination | G28: Residents report discoloured water with an odour from the community hand pump; suspected faecal contamination after heavy rain. | H28: 12 | I28: High | J28: Received | L28: =IF(K28="","",K28-B28) | M28: Yes | N28: Water point sampled; chlorination advised; community sensitised on boiling.
A29: HC-2026-0026 | B29: 46057 | C29: =MONTH(B29) -> 2 | D29: Montserrado | E29: Brewerville | F29: Chemical Exposure | G29: Possible chemical exposure reported after handling of unlabelled containers at a nearby facility. | H29: 1 | I29: Low | J29: Findings Presented | L29: =IF(K29="","",K29-B29) | M29: No | N29: Site visited with Chemical Unit; containers secured for inventory audit.
A30: HC-2026-0027 | B30: 46056 | C30: =MONTH(B30) -> 2 | D30: Montserrado | E30: Caldwell | F30: Waste Dumping | G30: Unauthorised dumping of mixed and medical waste on vacant land; scavenging by children reported. | H30: 0 | I30: Low | J30: Received | L30: =IF(K30="","",K30-B30) | M30: No | N30: Dumpsite cleared; warning notice served; monthly surveillance added.
A31: HC-2026-0028 | B31: 46068 | C31: =MONTH(B31) -> 2 | D31: Montserrado | E31: West Point | F31: Air Quality / Smoke & Dust | G31: Dust and smoke from open burning of waste; households report coughing and eye irritation. | H31: 2 | I31: Low | J31: Findings Presented | L31: =IF(K31="","",K31-B31) | M31: No | N31: Air sampling conducted; operator directed to suppress dust and stop open burning.
A32: HC-2026-0029 | B32: 46074 | C32: =MONTH(B32) -> 2 | D32: Margibi | E32: Firestone | F32: Drinking Water Contamination | G32: Residents report discoloured water with an odour from the community hand pump; suspected faecal contamination after heavy rain. | H32: 47 | I32: Critical | J32: Closed | K32: 46084 | L32: =IF(K32="","",K32-B32) -> 10 | M32: Yes | N32: Water point sampled; chlorination advised; community sensitised on boiling.
A33: HC-2026-0030 | B33: 46091 | C33: =MONTH(B33) -> 3 | D33: Grand Bassa | E33: Buchanan | F33: Sanitation | G33: Overflowing latrine / open defecation near a dwelling; residents report diarrhoeal illness, mostly in children under five. | H33: 6 | I33: Medium | J33: Closed | K33: 46109 | L33: =IF(K33="","",K33-B33) -> 18 | M33: Yes | N33: Referred to county health team; latrine disinfection and clean-up ordered.
A34: HC-2026-0031 | B34: 46112 | C34: =MONTH(B34) -> 3 | D34: Montserrado | E34: West Point | F34: Sanitation | G34: Overflowing latrine / open defecation near a dwelling; residents report diarrhoeal illness, mostly in children under five. | H34: 24 | I34: High | J34: Closed | K34: 46121 | L34: =IF(K34="","",K34-B34) -> 9 | M34: Yes | N34: Referred to county health team; latrine disinfection and clean-up ordered.
A35: HC-2026-0032 | B35: 46085 | C35: =MONTH(B35) -> 3 | D35: Nimba | E35: Saclepea | F35: Air Quality / Smoke & Dust | G35: Dust and smoke from open burning of waste; households report coughing and eye irritation. | H35: 5 | I35: Medium | J35: Closed | K35: 46105 | L35: =IF(K35="","",K35-B35) -> 20 | M35: No | N35: Air sampling conducted; operator directed to suppress dust and stop open burning.
A36: HC-2026-0033 | B36: 46085 | C36: =MONTH(B36) -> 3 | D36: Montserrado | E36: New Kru Town | F36: Sanitation | G36: Overflowing latrine / open defecation near a dwelling; residents report diarrhoeal illness, mostly in children under five. | H36: 6 | I36: Medium | J36: Closed | K36: 46108 | L36: =IF(K36="","",K36-B36) -> 23 | M36: Yes | N36: Referred to county health team; latrine disinfection and clean-up ordered.
A37: HC-2026-0034 | B37: 46107 | C37: =MONTH(B37) -> 3 | D37: Sinoe | E37: Greenville | F37: Noise | G37: Continuous low-frequency noise at night from night-time haulage. | H37: 2 | I37: Low | J37: Findings Presented | L37: =IF(K37="","",K37-B37) | M37: No | N37: Noise measurement taken; operator advised on night-time operating hours.
A38: HC-2026-0035 | B38: 46085 | C38: =MONTH(B38) -> 3 | D38: Nimba | E38: Butuo | F38: Chemical Exposure | G38: Possible chemical exposure reported after handling of unlabelled containers at a nearby facility. | H38: 9 | I38: Medium | J38: Received | L38: =IF(K38="","",K38-B38) | M38: No | N38: Site visited with Chemical Unit; containers secured for inventory audit.
A39: HC-2026-0036 | B39: 46094 | C39: =MONTH(B39) -> 3 | D39: Montserrado | E39: Johnsonville | F39: Air Quality / Smoke & Dust | G39: Dust and smoke from open burning of waste; households report coughing and eye irritation. | H39: 14 | I39: High | J39: Received | L39: =IF(K39="","",K39-B39) | M39: No | N39: Air sampling conducted; operator directed to suppress dust and stop open burning.
A40: HC-2026-0037 | B40: 46085 | C40: =MONTH(B40) -> 3 | D40: Grand Cape Mount | E40: Tieni | F40: Drinking Water Contamination | G40: Residents report discoloured water with an odour from the community hand pump; suspected faecal contamination after heavy rain. | H40: 34 | I40: Critical | J40: Investigating | L40: =IF(K40="","",K40-B40) | M40: Yes | N40: Water point sampled; chlorination advised; community sensitised on boiling.
...

Sheet Facility Inspections
A1: Facility Inspections - Environmental Health Risk
A2: One row per inspection. Health Risk Score is the inspecting officer's assessment: 1-3 low, 4-6 moderate, 7-10 high.
A3: Inspection ID | B3: Inspection Date | C3: Month | D3: County | E3: Facility | F3: Facility Type | G3: Outcome | H3: Health Risk Score (1-10) | I3: Key Findings | J3: Follow-up Required | K3: Follow-up Complete | L3: Inspector
A4: SI-2026-0001 | B4: 46034 | C4: =MONTH(B4) -> 1 | D4: Montserrado | E4: ArcelorMittal Buchanan | F4: Industrial Plant | G4: Compliant | H4: 3 | I4: Limits and record-keeping in order; no corrective action required. | J4: No | K4: No | L4: S. Dolo
A5: SI-2026-0002 | B5: 46042 | C5: =MONTH(B5) -> 1 | D5: Bong | E5: Gbarnga Community Water Point | F5: Water Treatment / Supply | G5: Non-Compliant | H5: 7 | I5: Radiation warning signage and access control missing at source store. | J5: Yes | K5: Yes | L5: L. Gbessay
A6: SI-2026-0003 | B6: 46053 | C6: =MONTH(B6) -> 1 | D6: Grand Cape Mount | E6: Robertsport Community Water Point | F6: Water Treatment / Supply | G6: Non-Compliant | H6: 7 | I6: Waste stored uncovered on site; corrective action plan requested. | J6: Yes | K6: Yes | L6: L. Gbessay
A7: SI-2026-0004 | B7: 46033 | C7: =MONTH(B7) -> 1 | D7: Bong | E7: Cavalla Rubber Corporation | F7: Industrial Plant | G7: Compliant | H7: 3 | I7: Monitoring records complete for the period under review. | J7: No | K7: No | L7: D. Yarkpawolo
A8: SI-2026-0005 | B8: 46051 | C8: =MONTH(B8) -> 1 | D8: Montserrado | E8: West Point Community Water Point | F8: School | G8: Compliant | H8: 3 | I8: Limits and record-keeping in order; no corrective action required. | J8: No | K8: No | L8: L. Gbessay
A9: SI-2026-0006 | B9: 46026 | C9: =MONTH(B9) -> 1 | D9: Montserrado | E9: Firestone Rubber Plantation | F9: Mining Site | G9: Compliant | H9: 2 | I9: Monitoring records complete for the period under review. | J9: No | K9: No | L9: A. Kollie
A10: SI-2026-0007 | B10: 46027 | C10: =MONTH(B10) -> 1 | D10: Grand Bassa | E10: Edina Health Center | F10: Hospital / Clinic | G10: Non-Compliant | H10: 10 | I10: Water supply point unprotected; risk of contamination confirmed. | J10: Yes | K10: No | L10: M. Toe
A11: SI-2026-0008 | B11: 46044 | C11: =MONTH(B11) -> 1 | D11: Grand Bassa | E11: Bea Mountain Mining | F11: Mining Site | G11: Non-Compliant | H11: 8 | I11: Waste stored uncovered on site; corrective action plan requested. | J11: Yes | K11: No | L11: D. Yarkpawolo
A12: SI-2026-0009 | B12: 46045 | C12: =MONTH(B12) -> 1 | D12: Gbarpolu | E12: Kongba Community Water Point | F12: Water Treatment / Supply | G12: Compliant | H12: 4 | I12: Monitoring records complete for the period under review. | J12: No | K12: No | L12: F. Gbato
A13: SI-2026-0010 | B13: 46030 | C13: =MONTH(B13) -> 1 | D13: Bomi | E13: Nimba Western Range Iron Ore | F13: Industrial Plant | G13: Compliant | H13: 2 | I13: Minor housekeeping notes given; no compliance gap identified. | J13: No | K13: No | L13: S. Dolo
A14: SI-2026-0011 | B14: 46051 | C14: =MONTH(B14) -> 1 | D14: Nimba | E14: Liberia Petroleum Refinery | F14: Industrial Plant | G14: Compliant | H14: 2 | I14: Monitoring records complete for the period under review. | J14: No | K14: No | L14: M. Toe
A15: SI-2026-0012 | B15: 46057 | C15: =MONTH(B15) -> 2 | D15: Grand Bassa | E15: Buchanan Government Hospital | F15: Hospital / Clinic | G15: Compliant | H15: 3 | I15: Minor housekeeping notes given; no compliance gap identified. | J15: No | K15: No | L15: M. Toe
... A85: SI-2026-0082 | B85: 46254 | C85: =MONTH(B85) -> 8 | D85: Bong | E85: Liberia Cement Corporation | F85: Industrial Plant | G85: Non-Compliant | H85: 7 | I85: Water supply point unprotected; risk of contamination confirmed. | J85: Yes | K85: Yes | L85: F. Gbato

Sheet Radiation Safety
A1: Radiation Safety - Facility and Worker Protection
A2: One row per licensed facility. Dose is the average annual effective dose per monitored worker against the IAEA 20 mSv occupational limit.
A3: Facility | B3: County | C3: Facility Type | D3: Sources Inventoried | E3: Workers Monitored | F3: Avg Annual Dose (mSv) | G3: Within 20 mSv Limit | H3: PPE Compliance | I3: Instrument Calibration Current | J3: Last Inventory Date | K3: Notes
A4: JFK Memorial Hospital - Radiology | B4: Montserrado | C4: Medical | D4: 2 | E4: 3 | F4: 5.6 | G4: =IF(F4<=20.0,"Yes","No") -> Yes | H4: 0.8 | I4: Yes | J4: 46174 | K4: Source register complete; leak test scheduled.
A5: JFK Memorial Hospital - Radiotherapy | B5: Montserrado | C5: Medical | D5: 2 | E5: 3 | F5: 10.1 | G5: =IF(F5<=20.0,"Yes","No") -> Yes | H5: 0.95 | I5: Yes | J5: 46071 | K5: Licence current; next inventory due within 12 months.
A6: Redemption Hospital - Radiology | B6: Montserrado | C6: Medical | D6: 2 | E6: 3 | F6: 1.7 | G6: =IF(F6<=20.0,"Yes","No") -> Yes | H6: 0.8 | I6: Yes | J6: 46246 | K6: Instrument calibration overdue - follow-up inspection scheduled.
A7: St. Joseph's Catholic Hospital - Radiology | B7: Montserrado | C7: Medical | D7: 1 | E7: 11 | F7: 23.5 | G7: =IF(F7<=20.0,"Yes","No") -> No | H7: 0.89 | I7: Yes | J7: 46032 | K7: Instrument calibration overdue - follow-up inspection scheduled.
A8: C.H. Rennie Hospital - Radiology | B8: Margibi | C8: Medical | D8: 5 | E8: 2 | F8: 1.1 | G8: =IF(F8<=20.0,"Yes","No") -> Yes | H8: 0.83 | I8: Yes | J8: 46095 | K8: Source register complete; leak test scheduled.
A9: Phebe Hospital - Radiology | B9: Bong | C9: Medical | D9: 2 | E9: 2 | F9: 12.2 | G9: =IF(F9<=20.0,"Yes","No") -> Yes | H9: 0.7 | I9: No | J9: 46085 | K9: Source register complete; leak test scheduled.
A10: Ganta United Methodist Hospital - Radiology | B10: Nimba | C10: Medical | D10: 3 | E10: 6 | F10: 12.2 | G10: =IF(F10<=20.0,"Yes","No") -> Yes | H10: 0.71 | I10: Yes | J10: 46132 | K10: Dose records reviewed on site; filing to be improved.
A11: Tappita Referral Hospital - Radiology | B11: Nimba | C11: Medical | D11: 2 | E11: 19 | F11: 5.4 | G11: =IF(F11<=20.0,"Yes","No") -> Yes | H11: 1 | I11: Yes | J11: 46130 | K11: PPE stock low - resupply requested by facility.
A12: Buchanan Government Hospital - Radiology | B12: Grand Bassa | C12: Medical | D12: 2 | E12: 8 | F12: 0.6 | G12: =IF(F12<=20.0,"Yes","No") -> Yes | H12: 0.92 | I12: Yes | J12: 46233 | K12: Source register complete; leak test scheduled.
A13: Curran Lutheran Hospital - Radiology | B13: Lofa | C13: Medical | D13: 4 | E13: 2 | F13: 0.9 | G13: =IF(F13<=20.0,"Yes","No") -> Yes | H13: 0.7 | I13: Yes | J13: 46235 | K13: Instrument calibration overdue - follow-up inspection scheduled.
A14: St. Timothy Hospital - Radiology | B14: Grand Cape Mount | C14: Medical | D14: 1 | E14: 4 | F14: 3.6 | G14: =IF(F14<=20.0,"Yes","No") -> Yes | H14: 0.69 | I14: Yes | J14: 46148 | K14: PPE stock low - resupply requested by facility.
A15: Harper Hospital - Radiology | B15: Maryland | C15: Medical | D15: 4 | E15: 4 | F15: 11.9 | G15: =IF(F15<=20.0,"Yes","No") -> Yes | H15: 0.72 | I15: Yes | J15: 46053 | K15: Dose records reviewed on site; filing to be improved.
... A45: Grand Bassa Community College - XRF Analyser | B45: Grand Bassa | C45: Environmental | D45: 2 | E45: 19 | F45: 5.6 | G45: =IF(F45<=20.0,"Yes","No") -> Yes | H45: 0.9 | I45: No | J45: 46240 | K45: Instrument calibration overdue - follow-up inspection scheduled.

Sheet Reference
A1: Reference - Safety Limits and Controlled Lists
A2: The thresholds applied in the Lab Results sheet, and the lists that feed every dropdown in this workbook.
A4: Safety limits applied
A5: Medium | B5: Parameter | C5: Unit | D5: Limit Min | E5: Limit Max | F5: Basis
A6: Water | B6: Total Coliform | C6: CFU/100 mL | D6: 0 | E6: 0 | F6: WHO drinking-water guideline
A7: Water | B7: E. coli | C7: CFU/100 mL | D7: 0 | E7: 0 | F7: WHO drinking-water guideline
A8: Water | B8: Nitrate (as NO3) | C8: mg/L | D8: 0 | E8: 10 | F8: WHO drinking-water guideline
A9: Water | B9: Arsenic | C9: mg/L | D9: 0 | E9: 0.01 | F9: WHO drinking-water guideline
A10: Water | B10: Lead | C10: mg/L | D10: 0 | E10: 0.01 | F10: WHO drinking-water guideline
A11: Water | B11: Manganese | C11: mg/L | D11: 0 | E11: 0.4 | F11: WHO drinking-water guideline
A12: Water | B12: Iron | C12: mg/L | D12: 0 | E12: 0.3 | F12: WHO guideline (aesthetic)
A13: Water | B13: Turbidity | C13: NTU | D13: 0 | E13: 5 | F13: WHO drinking-water guideline
A14: Soil | B14: Lead | C14: mg/kg | D14: 0 | E14: 100 | F14: US EPA regional screening level (residential)
A15: Soil | B15: Arsenic | C15: mg/kg | D15: 0 | E15: 20 | F15: US EPA regional screening level (residential)
A16: Soil | B16: Mercury | C16: mg/kg | D16: 0 | E16: 1 | F16: US EPA regional screening level (residential)
A17: Soil | B17: Cadmium | C17: mg/kg | D17: 0 | E17: 3 | F17: US EPA regional screening level (residential)
... A22: Ambient Radiation | B22: Gamma Dose Rate | C22: uSv/h | D22: 0 | E22: 0.3 | F22: IAEA reference level - public exposure
A24: Controlled lists (these feed the dropdowns)
A25: County | C25: Medium | D25: Parameter | E25: Complaint Type | F25: Complaint Status | G25: Severity | H25: Facility Type | I25: Radiation Facility Type | J25: Source Type | K25: Inspection Outcome | L25: Yes / No
A26: Montserrado | C26: Water | D26: Total Coliform | E26: Drinking Water Contamination | F26: Received | G26: Low | H26: Hospital / Clinic | I26: Medical | J26: Community Borehole | K26: Compliant | L26: Yes
A27: Nimba | C27: Soil | D27: E. coli | E27: Air Quality / Smoke & Dust | F27: Investigating | G27: Medium | H27: Industrial Plant | I27: Industrial | J27: Hand-Dug Well | K27: Non-Compliant | L27: No
A28: Bong | C28: Air | D28: Nitrate (as NO3) | E28: Sanitation | F28: Findings Presented | G28: High | H28: Water Treatment / Supply | I28: Environmental | J28: River / Stream Intake | K28: Pending Review
A29: Grand Bassa | C29: Ambient Radiation | D29: Arsenic | E29: Waste Dumping | F29: Closed | G29: Critical | H29: School | J29: Public Tap Stand
A30: Margibi | D30: Lead | E30: Noise | H30: Mining Site | J30: Health Facility Supply
A31: Lofa | D31: Manganese | E31: Chemical Exposure | H31: Waste Facility | J31: School Water Point
A32: Grand Cape Mount | D32: Iron | J32: Farmland
A33: Sinoe | D33: Turbidity | J33: School Grounds
A34: Grand Gedeh | D34: Lead | J34: Playground
A35: Bomi | D35: Arsenic | J35: Dumpsite Perimeter
A36: Maryland | D36: Mercury | J36: Industrial Site
A37: Gbarpolu | D37: Cadmium | J37: Urban Roadside
D38: PM2.5 | J38: Industrial Perimeter
D39: PM10 | J39: Residential Area
D40: Nitrogen Dioxide (NO2) | J40: Dumpsite Perimeter
D41: Sulphur Dioxide (SO2) | J41: Market Area
D42: Gamma Dose Rate

Sheet Read Me
B2: ERRS Environmental & Public Health Dashboard - how to use this workbook
B4: What this is
B5: A one-page health picture for the department: what the environment is doing to people, and what the department is doing about it. It brings together the four health-relevant streams ERRS already records - laboratory results measured against safety limits, environmental health complaints and the illness cases behind them, facility inspections, and radiation worker protection.
B7: The sheets
B8: Dashboard | C8: The one-page view. Twelve KPI cards, eight charts. Every figure is a live formula - nothing is typed in by hand.
B9: Lab Results | C9: One row per sample: water, soil, air and ambient radiation readings against the applicable limit. The Within Limit and Exceedance Ratio columns calculate themselves.
B10: Health Complaints | C10: One row per complaint, including how many illness cases were reported and how long the complaint took to close.
B11: Facility Inspections | C11: One row per inspection, with a 1-10 health risk score and whether the follow-up was completed.
B12: Radiation Safety | C12: One row per licensed facility: sources inventoried, workers monitored, annual dose against the 20 mSv limit, PPE compliance and instrument calibration status.
B13: Reference | C13: The safety limits applied to each parameter, and the controlled lists behind every dropdown.
B14: CalcData | C14: The engine: the aggregates the KPI cards and charts read from. Leave it alone unless you are changing the dashboard itself.
B16: How to put real data in
B17: 1. Keep the column headings and the layout exactly as they are - the dashboard aggregates by column, not by position on the row.
B18: 2. Type new records on the next empty row of each sheet, or paste them in. The tables, dropdowns, conditional colours and every chart extend automatically.
B19: 3. Delete the sample rows when real records replace them, and delete any rows you do not need - the formulas count whatever is actually there.
B20: 4. The Month, Within Limit, Exceedance Ratio, Days to Resolve and Within 20 mSv Limit columns all hold formulas, not values - hover the column heading for a note saying what each one does. If you overwrite one by accident, copy it down from the row above to bring it back.
B21: 5. The dashboard recalculates the moment the data changes. If a figure looks stale, press F9.
B23: A note on the data in this copy
B24: The rows in this workbook are realistic sample data, not real records: they are generated to show what the dashboard looks like when it is working, and they are shaped around Liberia's rainy and dry seasons so the trends behave believably. Replace them with the department's own entries before any of this is used for a decision or shown outside the team.
B25: The limits in the Reference sheet are the widely used WHO guideline values, US EPA regional screening levels (for soil) and an IAEA reference level (for ambient dose rate). They are a sensible default, not a legal position - have the department confirm each threshold against Liberia's own national standards before publishing this anywhere.
B27: Regenerating or extending it
B28: This workbook is built by scripts/build_health_dashboard.py in the ERRS Manager repository (npm run health-dashboard). Editing that script and re-running it rebuilds the whole workbook from scratch - useful if the department wants different parameters, different limits, or another breakdown added.

Sheet CalcData
A1: CalcData - the engine behind the Dashboard
A2: Every KPI card and chart reads from this sheet. Each cell is a live formula over the data sheets - add rows and these follow automatically.
A4: 1. Monthly trend
A5: Month | B5: Month # | C5: Samples Tested | D5: Within Limits | E5: Exceedances | F5: Exceedance Rate | G5: Complaints | H5: Illness Cases
A6: Jan 2026 | B6: 1 | C6: =COUNTIFS('Lab Results'!$C$4:$C$839,$B6) -> 65 | D6: =COUNTIFS('Lab Results'!$C$4:$C$839,$B6,'Lab Results'!$M$4:$M$839,"Yes") -> 54 | E6: =COUNTIFS('Lab Results'!$C$4:$C$839,$B6,'Lab Results'!$M$4:$M$839,"No") -> 11 | F6: =IFERROR($E6/$C6,0) -> 0.16923077 | G6: =COUNTIFS('Health Complaints'!$C$4:$C$408,$B6) -> 14 | H6: =SUMIFS('Health Complaints'!$H$4:$H$408,'Health Complaints'!$C$4:$C$408,$B6) -> 123
A7: Feb 2026 | B7: 2 | C7: =COUNTIFS('Lab Results'!$C$4:$C$839,$B7) -> 64 | D7: =COUNTIFS('Lab Results'!$C$4:$C$839,$B7,'Lab Results'!$M$4:$M$839,"Yes") -> 54 | E7: =COUNTIFS('Lab Results'!$C$4:$C$839,$B7,'Lab Results'!$M$4:$M$839,"No") -> 10 | F7: =IFERROR($E7/$C7,0) -> 0.15625 | G7: =COUNTIFS('Health Complaints'!$C$4:$C$408,$B7) -> 15 | H7: =SUMIFS('Health Complaints'!$H$4:$H$408,'Health Complaints'!$C$4:$C$408,$B7) -> 189
A8: Mar 2026 | B8: 3 | C8: =COUNTIFS('Lab Results'!$C$4:$C$839,$B8) -> 68 | D8: =COUNTIFS('Lab Results'!$C$4:$C$839,$B8,'Lab Results'!$M$4:$M$839,"Yes") -> 59 | E8: =COUNTIFS('Lab Results'!$C$4:$C$839,$B8,'Lab Results'!$M$4:$M$839,"No") -> 9 | F8: =IFERROR($E8/$C8,0) -> 0.13235294 | G8: =COUNTIFS('Health Complaints'!$C$4:$C$408,$B8) -> 13 | H8: =SUMIFS('Health Complaints'!$H$4:$H$408,'Health Complaints'!$C$4:$C$408,$B8) -> 137
A9: Apr 2026 | B9: 4 | C9: =COUNTIFS('Lab Results'!$C$4:$C$839,$B9) -> 66 | D9: =COUNTIFS('Lab Results'!$C$4:$C$839,$B9,'Lab Results'!$M$4:$M$839,"Yes") -> 56 | E9: =COUNTIFS('Lab Results'!$C$4:$C$839,$B9,'Lab Results'!$M$4:$M$839,"No") -> 10 | F9: =IFERROR($E9/$C9,0) -> 0.15151515 | G9: =COUNTIFS('Health Complaints'!$C$4:$C$408,$B9) -> 10 | H9: =SUMIFS('Health Complaints'!$H$4:$H$408,'Health Complaints'!$C$4:$C$408,$B9) -> 119
A10: May 2026 | B10: 5 | C10: =COUNTIFS('Lab Results'!$C$4:$C$839,$B10) -> 71 | D10: =COUNTIFS('Lab Results'!$C$4:$C$839,$B10,'Lab Results'!$M$4:$M$839,"Yes") -> 62 | E10: =COUNTIFS('Lab Results'!$C$4:$C$839,$B10,'Lab Results'!$M$4:$M$839,"No") -> 9 | F10: =IFERROR($E10/$C10,0) -> 0.12676056 | G10: =COUNTIFS('Health Complaints'!$C$4:$C$408,$B10) -> 15 | H10: =SUMIFS('Health Complaints'!$H$4:$H$408,'Health Complaints'!$C$4:$C$408,$B10) -> 141
A11: Jun 2026 | B11: 6 | C11: =COUNTIFS('Lab Results'!$C$4:$C$839,$B11) -> 69 | D11: =COUNTIFS('Lab Results'!$C$4:$C$839,$B11,'Lab Results'!$M$4:$M$839,"Yes") -> 49 | E11: =COUNTIFS('Lab Results'!$C$4:$C$839,$B11,'Lab Results'!$M$4:$M$839,"No") -> 20 | F11: =IFERROR($E11/$C11,0) -> 0.28985507 | G11: =COUNTIFS('Health Complaints'!$C$4:$C$408,$B11) -> 12 | H11: =SUMIFS('Health Complaints'!$H$4:$H$408,'Health Complaints'!$C$4:$C$408,$B11) -> 127
A12: Jul 2026 | B12: 7 | C12: =COUNTIFS('Lab Results'!$C$4:$C$839,$B12) -> 66 | D12: =COUNTIFS('Lab Results'!$C$4:$C$839,$B12,'Lab Results'!$M$4:$M$839,"Yes") -> 45 | E12: =COUNTIFS('Lab Results'!$C$4:$C$839,$B12,'Lab Results'!$M$4:$M$839,"No") -> 21 | F12: =IFERROR($E12/$C12,0) -> 0.31818182 | G12: =COUNTIFS('Health Complaints'!$C$4:$C$408,$B12) -> 14 | H12: =SUMIFS('Health Complaints'!$H$4:$H$408,'Health Complaints'!$C$4:$C$408,$B12) -> 283
A13: Aug 2026 | B13: 8 | C13: =COUNTIFS('Lab Results'!$C$4:$C$839,$B13) -> 67 | D13: =COUNTIFS('Lab Results'!$C$4:$C$839,$B13,'Lab Results'!$M$4:$M$839,"Yes") -> 53 | E13: =COUNTIFS('Lab Results'!$C$4:$C$839,$B13,'Lab Results'!$M$4:$M$839,"No") -> 14 | F13: =IFERROR($E13/$C13,0) -> 0.20895522 | G13: =COUNTIFS('Health Complaints'!$C$4:$C$408,$B13) -> 12 | H13: =SUMIFS('Health Complaints'!$H$4:$H$408,'Health Complaints'!$C$4:$C$408,$B13) -> 42
A14: 2026 to date (Jan-Aug) | C14: =SUM(C6:C13) -> 536 | D14: =SUM(D6:D13) -> 432 | E14: =SUM(E6:E13) -> 104 | F14: =IFERROR($E14/$C14,0) -> 0.19402985 | G14: =SUM(G6:G13) -> 105 | H14: =SUM(H6:H13) -> 1161
A16: 2. By medium
A17: Medium | B17: Samples | C17: Within Limits | D17: Exceedances | E17: % Within Limits
A18: Water | B18: =COUNTIFS('Lab Results'!$G$4:$G$839,$A18) -> 282 | C18: =COUNTIFS('Lab Results'!$G$4:$G$839,$A18,'Lab Results'!$M$4:$M$839,"Yes") -> 228 | D18: =$B18-$C18 -> 54 | E18: =IFERROR($C18/$B18,0) -> 0.80851064
A19: Soil | B19: =COUNTIFS('Lab Results'!$G$4:$G$839,$A19) -> 81 | C19: =COUNTIFS('Lab Results'!$G$4:$G$839,$A19,'Lab Results'!$M$4:$M$839,"Yes") -> 60 | D19: =$B19-$C19 -> 21 | E19: =IFERROR($C19/$B19,0) -> 0.74074074
A20: Air | B20: =COUNTIFS('Lab Results'!$G$4:$G$839,$A20) -> 127 | C20: =COUNTIFS('Lab Results'!$G$4:$G$839,$A20,'Lab Results'!$M$4:$M$839,"Yes") -> 100 | D20: =$B20-$C20 -> 27 | E20: =IFERROR($C20/$B20,0) -> 0.78740157
A21: Ambient Radiation | B21: =COUNTIFS('Lab Results'!$G$4:$G$839,$A21) -> 46 | C21: =COUNTIFS('Lab Results'!$G$4:$G$839,$A21,'Lab Results'!$M$4:$M$839,"Yes") -> 44 | D21: =$B21-$C21 -> 2 | E21: =IFERROR($C21/$B21,0) -> 0.95652174
A23: 3. Parameters ranked by exceedances
A24: Parameter | B24: Medium | C24: Samples | D24: Exceedances | E24: Exceedance Rate | F24: Avg Result / Limit
A25: Total Coliform | B25: Water | C25: =COUNTIFS('Lab Results'!$H$4:$H$839,$A25,'Lab Results'!$G$4:$G$839,$B25) -> 39 | D25: =COUNTIFS('Lab Results'!$H$4:$H$839,$A25,'Lab Results'!$G$4:$G$839,$B25,'Lab Results'!$M$4:$M$839,"No") -> 12 | E25: =IFERROR($D25/$C25,0) -> 0.30769231 | F25: =IFERROR(AVERAGEIFS('Lab Results'!$N$4:$N$839,'Lab Results'!$H$4:$H$839,$A25,'Lab Results'!$G$4:$G$839,$B25),0) -> 0
A26: Mercury | B26: Soil | C26: =COUNTIFS('Lab Results'!$H$4:$H$839,$A26,'Lab Results'!$G$4:$G$839,$B26) -> 28 | D26: =COUNTIFS('Lab Results'!$H$4:$H$839,$A26,'Lab Results'!$G$4:$G$839,$B26,'Lab Results'!$M$4:$M$839,"No") -> 9 | E26: =IFERROR($D26/$C26,0) -> 0.32142857 | F26: =IFERROR(AVERAGEIFS('Lab Results'!$N$4:$N$839,'Lab Results'!$H$4:$H$839,$A26,'Lab Results'!$G$4:$G$839,$B26),0) -> 1.1321429
A27: PM2.5 | B27: Air | C27: =COUNTIFS('Lab Results'!$H$4:$H$839,$A27,'Lab Results'!$G$4:$G$839,$B27) -> 30 | D27: =COUNTIFS('Lab Results'!$H$4:$H$839,$A27,'Lab Results'!$G$4:$G$839,$B27,'Lab Results'!$M$4:$M$839,"No") -> 8 | E27: =IFERROR($D27/$C27,0) -> 0.26666667 | F27: =IFERROR(AVERAGEIFS('Lab Results'!$N$4:$N$839,'Lab Results'!$H$4:$H$839,$A27,'Lab Results'!$G$4:$G$839,$B27),0) -> 0.93333333
A28: Manganese | B28: Water | C28: =COUNTIFS('Lab Results'!$H$4:$H$839,$A28,'Lab Results'!$G$4:$G$839,$B28) -> 32 | D28: =COUNTIFS('Lab Results'!$H$4:$H$839,$A28,'Lab Results'!$G$4:$G$839,$B28,'Lab Results'!$M$4:$M$839,"No") -> 8 | E28: =IFERROR($D28/$C28,0) -> 0.25 | F28: =IFERROR(AVERAGEIFS('Lab Results'!$N$4:$N$839,'Lab Results'!$H$4:$H$839,$A28,'Lab Results'!$G$4:$G$839,$B28),0) -> 0.88125
A29: Turbidity | B29: Water | C29: =COUNTIFS('Lab Results'!$H$4:$H$839,$A29,'Lab Results'!$G$4:$G$839,$B29) -> 33 | D29: =COUNTIFS('Lab Results'!$H$4:$H$839,$A29,'Lab Results'!$G$4:$G$839,$B29,'Lab Results'!$M$4:$M$839,"No") -> 8 | E29: =IFERROR($D29/$C29,0) -> 0.24242424 | F29: =IFERROR(AVERAGEIFS('Lab Results'!$N$4:$N$839,'Lab Results'!$H$4:$H$839,$A29,'Lab Results'!$G$4:$G$839,$B29),0) -> 0.93333333
A30: Arsenic | B30: Soil | C30: =COUNTIFS('Lab Results'!$H$4:$H$839,$A30,'Lab Results'!$G$4:$G$839,$B30) -> 14 | D30: =COUNTIFS('Lab Results'!$H$4:$H$839,$A30,'Lab Results'!$G$4:$G$839,$B30,'Lab Results'!$M$4:$M$839,"No") -> 7 | E30: =IFERROR($D30/$C30,0) -> 0.5 | F30: =IFERROR(AVERAGEIFS('Lab Results'!$N$4:$N$839,'Lab Results'!$H$4:$H$839,$A30,'Lab Results'!$G$4:$G$839,$B30),0) -> 1.3485714
A31: Nitrogen Dioxide (NO2) | B31: Air | C31: =COUNTIFS('Lab Results'!$H$4:$H$839,$A31,'Lab Results'!$G$4:$G$839,$B31) -> 31 | D31: =COUNTIFS('Lab Results'!$H$4:$H$839,$A31,'Lab Results'!$G$4:$G$839,$B31,'Lab Results'!$M$4:$M$839,"No") -> 7 | E31: =IFERROR($D31/$C31,0) -> 0.22580645 | F31: =IFERROR(AVERAGEIFS('Lab Results'!$N$4:$N$839,'Lab Results'!$H$4:$H$839,$A31,'Lab Results'!$G$4:$G$839,$B31),0) -> 0.94806452
A32: PM10 | B32: Air | C32: =COUNTIFS('Lab Results'!$H$4:$H$839,$A32,'Lab Results'!$G$4:$G$839,$B32) -> 39 | D32: =COUNTIFS('Lab Results'!$H$4:$H$839,$A32,'Lab Results'!$G$4:$G$839,$B32,'Lab Results'!$M$4:$M$839,"No") -> 7 | E32: =IFERROR($D32/$C32,0) -> 0.17948718 | F32: =IFERROR(AVERAGEIFS('Lab Results'!$N$4:$N$839,'Lab Results'!$H$4:$H$839,$A32,'Lab Results'!$G$4:$G$839,$B32),0) -> 0.76564103
A33: Lead | B33: Water | C33: =COUNTIFS('Lab Results'!$H$4:$H$839,$A33,'Lab Results'!$G$4:$G$839,$B33) -> 47 | D33: =COUNTIFS('Lab Results'!$H$4:$H$839,$A33,'Lab Results'!$G$4:$G$839,$B33,'Lab Results'!$M$4:$M$839,"No") -> 7 | E33: =IFERROR($D33/$C33,0) -> 0.14893617 | F33: =IFERROR(AVERAGEIFS('Lab Results'!$N$4:$N$839,'Lab Results'!$H$4:$H$839,$A33,'Lab Results'!$G$4:$G$839,$B33),0) -> 0.71851064
A34: Iron | B34: Water | C34: =COUNTIFS('Lab Results'!$H$4:$H$839,$A34,'Lab Results'!$G$4:$G$839,$B34) -> 31 | D34: =COUNTIFS('Lab Results'!$H$4:$H$839,$A34,'Lab Results'!$G$4:$G$839,$B34,'Lab Results'!$M$4:$M$839,"No") -> 6 | E34: =IFERROR($D34/$C34,0) -> 0.19354839 | F34: =IFERROR(AVERAGEIFS('Lab Results'!$N$4:$N$839,'Lab Results'!$H$4:$H$839,$A34,'Lab Results'!$G$4:$G$839,$B34),0) -> 0.70107527
A36: 4. Complaints by type
A37: Complaint Type | B37: Complaints | C37: Illness Cases | D37: Avg Days to Resolve
A38: Drinking Water Contamination | B38: =COUNTIFS('Health Complaints'!$F$4:$F$408,$A38) -> 33 | C38: =SUMIFS('Health Complaints'!$H$4:$H$408,'Health Complaints'!$F$4:$F$408,$A38) -> 691 | D38: =IFERROR(AVERAGEIFS('Health Complaints'!$L$4:$L$408,'Health Complaints'!$F$4:$F$408,$A38),0) -> 15.333333
A39: Air Quality / Smoke & Dust | B39: =COUNTIFS('Health Complaints'!$F$4:$F$408,$A39) -> 20 | C39: =SUMIFS('Health Complaints'!$H$4:$H$408,'Health Complaints'!$F$4:$F$408,$A39) -> 189 | D39: =IFERROR(AVERAGEIFS('Health Complaints'!$L$4:$L$408,'Health Complaints'!$F$4:$F$408,$A39),0) -> 17.4
A40: Sanitation | B40: =COUNTIFS('Health Complaints'!$F$4:$F$408,$A40) -> 16 | C40: =SUMIFS('Health Complaints'!$H$4:$H$408,'Health Complaints'!$F$4:$F$408,$A40) -> 179 | D40: =IFERROR(AVERAGEIFS('Health Complaints'!$L$4:$L$408,'Health Complaints'!$F$4:$F$408,$A40),0) -> 20.090909
A41: Waste Dumping | B41: =COUNTIFS('Health Complaints'!$F$4:$F$408,$A41) -> 18 | C41: =SUMIFS('Health Complaints'!$H$4:$H$408,'Health Complaints'!$F$4:$F$408,$A41) -> 63 | D41: =IFERROR(AVERAGEIFS('Health Complaints'!$L$4:$L$408,'Health Complaints'!$F$4:$F$408,$A41),0) -> 30.1
A42: Noise | B42: =COUNTIFS('Health Complaints'!$F$4:$F$408,$A42) -> 10 | C42: =SUMIFS('Health Complaints'!$H$4:$H$408,'Health Complaints'!$F$4:$F$408,$A42) -> 9 | D42: =IFERROR(AVERAGEIFS('Health Complaints'!$L$4:$L$408,'Health Complaints'!$F$4:$F$408,$A42),0) -> 9.25
A43: Chemical Exposure | B43: =COUNTIFS('Health Complaints'!$F$4:$F$408,$A43) -> 8 | C43: =SUMIFS('Health Complaints'!$H$4:$H$408,'Health Complaints'!$F$4:$F$408,$A43) -> 30 | D43: =IFERROR(AVERAGEIFS('Health Complaints'!$L$4:$L$408,'Health Complaints'!$F$4:$F$408,$A43),0) -> 30.2
A45: 5. Complaint status
...
